Workbook

Sheet XXXXXX

Sheet PMC.D
A1: Maintenance Calender
A2: Daily Cleanliness | B2: Planed Maintenance Calender
A3: メニューＳ・ポスター | B3: カップウォーマー | C3: weekly
A4: レジおよび周辺 | B4: ガッター/グループ | D4: 1 | E4: 月
A5: 物販棚 | B5: ホルダー/スパウト | D5: Daily Cleanliness | J5: PMC
A6: ディスプレイ棚（入口側） | B6: ｸﾞﾗｲﾝﾀﾞｰホッパー
A7: ディスプレイ棚（奥側） | B7: ホイップマシンフィルター
A8: デシャップ周辺 | B8: ビールサーバー
A9: カウンター下部 | B9: 冷蔵/冷凍庫フィルター
A10: デシャップランプシェード | B10: 製氷機フィルター
A11: コンディメント各容器 | B11: ショーケースフィルター
A12: フード食材棚 | B12: ミキシングボトル分解漂白
A13: 掃除用具 | B13: レギュラーＣシャワー | C13: Monthiy | D13: 2 | E13: 火
A14: ウォッシャー周辺 | B14: 冷凍/冷蔵コンデンサー | D14: Daily Cleanliness | J14: PMC
A15: デシャップ冷蔵庫フィルター | B15: 排気ダクト
A16: ドリンク冷蔵庫フィルター | B16: 空調機器（フィルター清掃）
A17: フード冷蔵庫フィルター | B17: マシンプログラミング
A18: ４枚扉フード冷蔵庫フィルター | B18: ｸﾞﾗｲﾝﾀﾞｰコンテナ内部 | C18: 2Month
A19: フード冷凍庫・フィルター | B19: ｸﾞﾗｲﾝﾀﾞｰマイクロスィッチＢＯＸ
A20: 製氷機フィルター | B20: ｸﾞﾗｲﾝﾀﾞｰ バーツ交換
A21: ショーケースフィルター | B21: ｸﾞﾗｲﾝﾀﾞｰ 底部清掃
A22: ホイップマシンフィルター | D22: 3 | E22: 水
A23: ワインラック | D23: Daily Cleanliness | J23: PMC
A24: ビールサーバー
A25: グラニータマシン
A26: グラニータマシン底部
A27: ダクトフードおよび周辺
A28: 排水溝蓋デッキブラシ
A29: 窓ガラス（禁煙席）
A30: 窓ガラス（喫煙席）
A31: 窓ガラス（ハイテーブル） | D31: 4 | E31: 木
A32: 窓ガラス（蛇腹扉） | D32: Daily Cleanliness | J32: PMC
A33: ゴミ箱
D40: 5 | E40: 金
D41: Daily Cleanliness | J41: PMC
D49: 6 | E49: 土
D50: Daily Cleanliness | J50: PMC

Sheet セールスアクション 
B1: Ｓales Action
B3: 1 | C3: 週目
B4: Ｓales Action
B11: 2 | C11: 週目
B12: Ｓales Action
B19: 3 | C19: 週目
B20: Ｓales Action
B27: 4 | C27: 週目
B28: Ｓales Action
B35: 5 | C35: 週目
B36: Ｓales Action

Sheet 1
K1: =ﾃﾞｰﾀ入力!B4 -> 新宿三丁目 | V1: 店 | AC1: =ﾃﾞｰﾀ入力!B5 -> 4 | AJ1: 月 | AN1: 1 | AR1: 日 | AZ1: =DATE(ﾃﾞｰﾀ入力!B3,ﾃﾞｰﾀ入力!B5,AN1) -> 46113 | BD1: 曜日 | BT1: 曜日 | CA1: 1
L2: 0.20833333 | P2: 0.25 | T2: 7:00 | X2: 8:00 | AB2: 9:00 | AF2: 10:00 | AJ2: 11:00 | AN2: 12:00 | AR2: 13:00 | AV2: 14:00 | AZ2: 15:00 | BD2: 16:00 | BH2: 17:00 | BL2: 18:00 | BP2: 19:00 | BT2: 20:00 | BX2: 21:00 | CB2: 22:00 | CF2: 23:00 | CJ2: 24:00
I3: 実行計画売上（千円） | K3: PLAN | L3: =CHOOSE(CA1,ﾃﾞｰﾀ入力!X4,ﾃﾞｰﾀ入力!X5,ﾃﾞｰﾀ入力!X6,ﾃﾞｰﾀ入力!X7,ﾃﾞｰﾀ入力!X8,ﾃﾞｰﾀ入力!X9) -> 0 | P3: =CHOOSE($CA$1,ﾃﾞｰﾀ入力!Y$4,ﾃﾞｰﾀ入力!Y$5,ﾃﾞｰﾀ入力!Y$6,ﾃﾞｰﾀ入力!Y$7,ﾃﾞｰﾀ入力!Y$8,ﾃﾞｰﾀ入力!Y$9) -> 0 | T3: =CHOOSE($CA$1,ﾃﾞｰﾀ入力!Z$4,ﾃﾞｰﾀ入力!Z$5,ﾃﾞｰﾀ入力!Z$6,ﾃﾞｰﾀ入力!Z$7,ﾃﾞｰﾀ入力!Z$8,ﾃﾞｰﾀ入力!Z$9) -> 0 | X3: =CHOOSE($CA$1,ﾃﾞｰﾀ入力!AA$4,ﾃﾞｰﾀ入力!AA$5,ﾃﾞｰﾀ入力!AA$6,ﾃﾞｰﾀ入力!AA$7,ﾃﾞｰﾀ入力!AA$8,ﾃﾞｰﾀ入力!AA$9) -> 7 | AB3: =CHOOSE($CA$1,ﾃﾞｰﾀ入力!AB$4,ﾃﾞｰﾀ入力!AB$5,ﾃﾞｰﾀ入力!AB$6,ﾃﾞｰﾀ入力!AB$7,ﾃﾞｰﾀ入力!AB$8,ﾃﾞｰﾀ入力!AB$9) -> 13 | AF3: =CHOOSE($CA$1,ﾃﾞｰﾀ入力!AC$4,ﾃﾞｰﾀ入力!AC$5,ﾃﾞｰﾀ入力!AC$6,ﾃﾞｰﾀ入力!AC$7,ﾃﾞｰﾀ入力!AC$8,ﾃﾞｰﾀ入力!AC$9) -> 13 | AJ3: =CHOOSE($CA$1,ﾃﾞｰﾀ入力!AD$4,ﾃﾞｰﾀ入力!AD$5,ﾃﾞｰﾀ入力!AD$6,ﾃﾞｰﾀ入力!AD$7,ﾃﾞｰﾀ入力!AD$8,ﾃﾞｰﾀ入力!AD$9) -> 18 | AN3: =CHOOSE($CA$1,ﾃﾞｰﾀ入力!AE$4,ﾃﾞｰﾀ入力!AE$5,ﾃﾞｰﾀ入力!AE$6,ﾃﾞｰﾀ入力!AE$7,ﾃﾞｰﾀ入力!AE$8,ﾃﾞｰﾀ入力!AE$9) -> 28 | AR3: =CHOOSE($CA$1,ﾃﾞｰﾀ入力!AF$4,ﾃﾞｰﾀ入力!AF$5,ﾃﾞｰﾀ入力!AF$6,ﾃﾞｰﾀ入力!AF$7,ﾃﾞｰﾀ入力!AF$8,ﾃﾞｰﾀ入力!AF$9) -> 31 | AV3: =CHOOSE($CA$1,ﾃﾞｰﾀ入力!AG$4,ﾃﾞｰﾀ入力!AG$5,ﾃﾞｰﾀ入力!AG$6,ﾃﾞｰﾀ入力!AG$7,ﾃﾞｰﾀ入力!AG$8,ﾃﾞｰﾀ入力!AG$9) -> 30 | AZ3: =CHOOSE($CA$1,ﾃﾞｰﾀ入力!AH$4,ﾃﾞｰﾀ入力!AH$5,ﾃﾞｰﾀ入力!AH$6,ﾃﾞｰﾀ入力!AH$7,ﾃﾞｰﾀ入力!AH$8,ﾃﾞｰﾀ入力!AH$9) -> 32 | BD3: =CHOOSE($CA$1,ﾃﾞｰﾀ入力!AI$4,ﾃﾞｰﾀ入力!AI$5,ﾃﾞｰﾀ入力!AI$6,ﾃﾞｰﾀ入力!AI$7,ﾃﾞｰﾀ入力!AI$8,ﾃﾞｰﾀ入力!AI$9) -> 30 | BH3: =CHOOSE($CA$1,ﾃﾞｰﾀ入力!AJ$4,ﾃﾞｰﾀ入力!AJ$5,ﾃﾞｰﾀ入力!AJ$6,ﾃﾞｰﾀ入力!AJ$7,ﾃﾞｰﾀ入力!AJ$8,ﾃﾞｰﾀ入力!AJ$9) -> 21 | BL3: =CHOOSE($CA$1,ﾃﾞｰﾀ入力!AK$4,ﾃﾞｰﾀ入力!AK$5,ﾃﾞｰﾀ入力!AK$6,ﾃﾞｰﾀ入力!AK$7,ﾃﾞｰﾀ入力!AK$8,ﾃﾞｰﾀ入力!AK$9) -> 15 | BP3: =CHOOSE($CA$1,ﾃﾞｰﾀ入力!AL$4,ﾃﾞｰﾀ入力!AL$5,ﾃﾞｰﾀ入力!AL$6,ﾃﾞｰﾀ入力!AL$7,ﾃﾞｰﾀ入力!AL$8,ﾃﾞｰﾀ入力!AL$9) -> 16 | BT3: =CHOOSE($CA$1,ﾃﾞｰﾀ入力!AM$4,ﾃﾞｰﾀ入力!AM$5,ﾃﾞｰﾀ入力!AM$6,ﾃﾞｰﾀ入力!AM$7,ﾃﾞｰﾀ入力!AM$8,ﾃﾞｰﾀ入力!AM$9) -> 12 | BX3: =CHOOSE($CA$1,ﾃﾞｰﾀ入力!AN$4,ﾃﾞｰﾀ入力!AN$5,ﾃﾞｰﾀ入力!AN$6,ﾃﾞｰﾀ入力!AN$7,ﾃﾞｰﾀ入力!AN$8,ﾃﾞｰﾀ入力!AN$9) -> 4 | CB3: =CHOOSE($CA$1,ﾃﾞｰﾀ入力!AO$4,ﾃﾞｰﾀ入力!AO$5,ﾃﾞｰﾀ入力!AO$6,ﾃﾞｰﾀ入力!AO$7,ﾃﾞｰﾀ入力!AO$8,ﾃﾞｰﾀ入力!AO$9) -> 0 | CF3: =CHOOSE($CA$1,ﾃﾞｰﾀ入力!AP$4,ﾃﾞｰﾀ入力!AP$5,ﾃﾞｰﾀ入力!AP$6,ﾃﾞｰﾀ入力!AP$7,ﾃﾞｰﾀ入力!AP$8,ﾃﾞｰﾀ入力!AP$9) -> 0 | CJ3: =CHOOSE($CA$1,ﾃﾞｰﾀ入力!AQ$4,ﾃﾞｰﾀ入力!AQ$5,ﾃﾞｰﾀ入力!AQ$6,ﾃﾞｰﾀ入力!AQ$7,ﾃﾞｰﾀ入力!AQ$8,ﾃﾞｰﾀ入力!AQ$9) -> 0 | CN3: =CHOOSE(CA1,ﾃﾞｰﾀ入力!V4,ﾃﾞｰﾀ入力!V5,ﾃﾞｰﾀ入力!V6,ﾃﾞｰﾀ入力!V7,ﾃﾞｰﾀ入力!V8,ﾃﾞｰﾀ入力!V9) -> 270
K4: 累計 | L4: =H4+L3 -> 0 | P4: =L4+P3 -> 0 | T4: =P4+T3 -> 0 | X4: =T4+X3 -> 7 | AB4: =X4+AB3 -> 20 | AF4: =AB4+AF3 -> 33 | AJ4: =AF4+AJ3 -> 51 | AN4: =AJ4+AN3 -> 79 | AR4: =AN4+AR3 -> 110 | AV4: =AV3+AR4 -> 140 | AZ4: =+AV4+AZ3 -> 172 | BD4: =AZ4+BD3 -> 202 | BH4: =BD4+BH3 -> 223 | BL4: =BH4+BL3 -> 238 | BP4: =BL4+BP3 -> 254 | BT4: =BP4+BT3 -> 266 | BX4: =BT4+BX3 -> 270 | CB4: =BX4+CB3 -> 270 | CF4: =CB4+CF3 -> 270 | CJ4: =CF4+CJ3 -> 270
I5: 売上ACTUAL（千円） | K5: ACTUAL | CN5: =SUM(P5:CM5) -> 0
K6: 累計 | CN6: =SUM(P6:CM6) -> 0
I7: 必要人員数 | K7: PLAN | L7: =IF(L3=0,0,LOOKUP(L3,ﾃﾞｰﾀ入力!$AU$12:$AU$32,ﾃﾞｰﾀ入力!$AV$12:$AV$32)) -> 0 | P7: =IF(P3=0,0,LOOKUP(P3,ﾃﾞｰﾀ入力!$AU$12:$AU$32,ﾃﾞｰﾀ入力!$AV$12:$AV$32)) -> 0 | T7: =IF(T3=0,0,LOOKUP(T3,ﾃﾞｰﾀ入力!$AU$12:$AU$32,ﾃﾞｰﾀ入力!$AV$12:$AV$32)) -> 0 | X7: =IF(X3=0,0,LOOKUP(X3,ﾃﾞｰﾀ入力!$AU$12:$AU$32,ﾃﾞｰﾀ入力!$AV$12:$AV$32)) -> 2 | AB7: =IF(AB3=0,0,LOOKUP(AB3,ﾃﾞｰﾀ入力!$AU$12:$AU$32,ﾃﾞｰﾀ入力!$AV$12:$AV$32)) -> 2 | AF7: =IF(AF3=0,0,LOOKUP(AF3,ﾃﾞｰﾀ入力!$AU$12:$AU$32,ﾃﾞｰﾀ入力!$AV$12:$AV$32)) -> 2 | AJ7: =IF(AJ3=0,0,LOOKUP(AJ3,ﾃﾞｰﾀ入力!$AU$12:$AU$32,ﾃﾞｰﾀ入力!$AV$12:$AV$32)) -> 2 | AN7: =IF(AN3=0,0,LOOKUP(AN3,ﾃﾞｰﾀ入力!$AU$12:$AU$32,ﾃﾞｰﾀ入力!$AV$12:$AV$32)) -> 4 | AR7: =IF(AR3=0,0,LOOKUP(AR3,ﾃﾞｰﾀ入力!$AU$12:$AU$32,ﾃﾞｰﾀ入力!$AV$12:$AV$32)) -> 4 | AV7: =IF(AV3=0,0,LOOKUP(AV3,ﾃﾞｰﾀ入力!$AU$12:$AU$32,ﾃﾞｰﾀ入力!$AV$12:$AV$32)) -> 4 | AZ7: =IF(AZ3=0,0,LOOKUP(AZ3,ﾃﾞｰﾀ入力!$AU$12:$AU$32,ﾃﾞｰﾀ入力!$AV$12:$AV$32)) -> 4 | BD7: =IF(BD3=0,0,LOOKUP(BD3,ﾃﾞｰﾀ入力!$AU$12:$AU$32,ﾃﾞｰﾀ入力!$AV$12:$AV$32)) -> 4 | BH7: =IF(BH3=0,0,LOOKUP(BH3,ﾃﾞｰﾀ入力!$AU$12:$AU$32,ﾃﾞｰﾀ入力!$AV$12:$AV$32)) -> 3 | BL7: =IF(BL3=0,0,LOOKUP(BL3,ﾃﾞｰﾀ入力!$AU$12:$AU$32,ﾃﾞｰﾀ入力!$AV$12:$AV$32)) -> 2 | BP7: =IF(BP3=0,0,LOOKUP(BP3,ﾃﾞｰﾀ入力!$AU$12:$AU$32,ﾃﾞｰﾀ入力!$AV$12:$AV$32)) -> 2 | BT7: =IF(BT3=0,0,LOOKUP(BT3,ﾃﾞｰﾀ入力!$AU$12:$AU$32,ﾃﾞｰﾀ入力!$AV$12:$AV$32)) -> 2 | BX7: =IF(BX3=0,0,LOOKUP(BX3,ﾃﾞｰﾀ入力!$AU$12:$AU$32,ﾃﾞｰﾀ入力!$AV$12:$AV$32)) -> 2 | CB7: =IF(CB3=0,0,LOOKUP(CB3,ﾃﾞｰﾀ入力!$AU$12:$AU$32,ﾃﾞｰﾀ入力!$AV$12:$AV$32)) -> 0 | CF7: =IF(CF3=0,0,LOOKUP(CF3,ﾃﾞｰﾀ入力!$AU$12:$AU$32,ﾃﾞｰﾀ入力!$AV$12:$AV$32)) -> 0 | CJ7: =IF(CJ3=0,0,LOOKUP(CJ3,ﾃﾞｰﾀ入力!$AU$12:$AU$32,ﾃﾞｰﾀ入力!$AV$12:$AV$32)) -> 0 | CN7: =SUM(P7:CM7) -> 39
I8: 休憩時間 | K8: PLAN | L8: =CHOOSE($CA$1,ﾃﾞｰﾀ入力!W13,ﾃﾞｰﾀ入力!W16,ﾃﾞｰﾀ入力!W19,ﾃﾞｰﾀ入力!W22,ﾃﾞｰﾀ入力!W25,ﾃﾞｰﾀ入力!W28) -> 0 | P8: =CHOOSE($CA$1,ﾃﾞｰﾀ入力!X13,ﾃﾞｰﾀ入力!X16,ﾃﾞｰﾀ入力!X19,ﾃﾞｰﾀ入力!X22,ﾃﾞｰﾀ入力!X25,ﾃﾞｰﾀ入力!X28) -> 0 | T8: =CHOOSE($CA$1,ﾃﾞｰﾀ入力!Y13,ﾃﾞｰﾀ入力!Y16,ﾃﾞｰﾀ入力!Y19,ﾃﾞｰﾀ入力!Y22,ﾃﾞｰﾀ入力!Y25,ﾃﾞｰﾀ入力!Y28) -> 0 | X8: =CHOOSE($CA$1,ﾃﾞｰﾀ入力!Z13,ﾃﾞｰﾀ入力!Z16,ﾃﾞｰﾀ入力!Z19,ﾃﾞｰﾀ入力!Z22,ﾃﾞｰﾀ入力!Z25,ﾃﾞｰﾀ入力!Z28) -> 0 | AB8: =CHOOSE($CA$1,ﾃﾞｰﾀ入力!AA13,ﾃﾞｰﾀ入力!AA16,ﾃﾞｰﾀ入力!AA19,ﾃﾞｰﾀ入力!AA22,ﾃﾞｰﾀ入力!AA25,ﾃﾞｰﾀ入力!AA28) -> 0 | AF8: =CHOOSE($CA$1,ﾃﾞｰﾀ入力!AB13,ﾃﾞｰﾀ入力!AB16,ﾃﾞｰﾀ入力!AB19,ﾃﾞｰﾀ入力!AB22,ﾃﾞｰﾀ入力!AB25,ﾃﾞｰﾀ入力!AB28) -> 0 | AJ8: =CHOOSE($CA$1,ﾃﾞｰﾀ入力!AC13,ﾃﾞｰﾀ入力!AC16,ﾃﾞｰﾀ入力!AC19,ﾃﾞｰﾀ入力!AC22,ﾃﾞｰﾀ入力!AC25,ﾃﾞｰﾀ入力!AC28) -> 0 | AN8: =CHOOSE($CA$1,ﾃﾞｰﾀ入力!AD13,ﾃﾞｰﾀ入力!AD16,ﾃﾞｰﾀ入力!AD19,ﾃﾞｰﾀ入力!AD22,ﾃﾞｰﾀ入力!AD25,ﾃﾞｰﾀ入力!AD28) -> 0 | AR8: =CHOOSE($CA$1,ﾃﾞｰﾀ入力!AE13,ﾃﾞｰﾀ入力!AE16,ﾃﾞｰﾀ入力!AE19,ﾃﾞｰﾀ入力!AE22,ﾃﾞｰﾀ入力!AE25,ﾃﾞｰﾀ入力!AE28) -> 0 | AV8: =CHOOSE($CA$1,ﾃﾞｰﾀ入力!AF13,ﾃﾞｰﾀ入力!AF16,ﾃﾞｰﾀ入力!AF19,ﾃﾞｰﾀ入力!AF22,ﾃﾞｰﾀ入力!AF25,ﾃﾞｰﾀ入力!AF28) -> 0 | AZ8: =CHOOSE($CA$1,ﾃﾞｰﾀ入力!AG13,ﾃﾞｰﾀ入力!AG16,ﾃﾞｰﾀ入力!AG19,ﾃﾞｰﾀ入力!AG22,ﾃﾞｰﾀ入力!AG25,ﾃﾞｰﾀ入力!AG28) -> 0 | BD8: =CHOOSE($CA$1,ﾃﾞｰﾀ入力!AH13,ﾃﾞｰﾀ入力!AH16,ﾃﾞｰﾀ入力!AH19,ﾃﾞｰﾀ入力!AH22,ﾃﾞｰﾀ入力!AH25,ﾃﾞｰﾀ入力!AH28) -> 0 | BH8: =CHOOSE($CA$1,ﾃﾞｰﾀ入力!AI13,ﾃﾞｰﾀ入力!AI16,ﾃﾞｰﾀ入力!AI19,ﾃﾞｰﾀ入力!AI22,ﾃﾞｰﾀ入力!AI25,ﾃﾞｰﾀ入力!AI28) -> 0 | BL8: =CHOOSE($CA$1,ﾃﾞｰﾀ入力!AJ13,ﾃﾞｰﾀ入力!AJ16,ﾃﾞｰﾀ入力!AJ19,ﾃﾞｰﾀ入力!AJ22,ﾃﾞｰﾀ入力!AJ25,ﾃﾞｰﾀ入力!AJ28) -> 0 | BP8: =CHOOSE($CA$1,ﾃﾞｰﾀ入力!AK13,ﾃﾞｰﾀ入力!AK16,ﾃﾞｰﾀ入力!AK19,ﾃﾞｰﾀ入力!AK22,ﾃﾞｰﾀ入力!AK25,ﾃﾞｰﾀ入力!AK28) -> 0 | BT8: =CHOOSE($CA$1,ﾃﾞｰﾀ入力!AL13,ﾃﾞｰﾀ入力!AL16,ﾃﾞｰﾀ入力!AL19,ﾃﾞｰﾀ入力!AL22,ﾃﾞｰﾀ入力!AL25,ﾃﾞｰﾀ入力!AL28) -> 0 | BX8: =CHOOSE($CA$1,ﾃﾞｰﾀ入力!AM13,ﾃﾞｰﾀ入力!AM16,ﾃﾞｰﾀ入力!AM19,ﾃﾞｰﾀ入力!AM22,ﾃﾞｰﾀ入力!AM25,ﾃﾞｰﾀ入力!AM28) -> 0 | CB8: =CHOOSE($CA$1,ﾃﾞｰﾀ入力!AN13,ﾃﾞｰﾀ入力!AN16,ﾃﾞｰﾀ入力!AN19,ﾃﾞｰﾀ入力!AN22,ﾃﾞｰﾀ入力!AN25,ﾃﾞｰﾀ入力!AN28) -> 0 | CF8: =CHOOSE($CA$1,ﾃﾞｰﾀ入力!AO13,ﾃﾞｰﾀ入力!AO16,ﾃﾞｰﾀ入力!AO19,ﾃﾞｰﾀ入力!AO22,ﾃﾞｰﾀ入力!AO25,ﾃﾞｰﾀ入力!AO28) -> 0 | CJ8: =CHOOSE($CA$1,ﾃﾞｰﾀ入力!AP13,ﾃﾞｰﾀ入力!AP16,ﾃﾞｰﾀ入力!AP19,ﾃﾞｰﾀ入力!AP22,ﾃﾞｰﾀ入力!AP25,ﾃﾞｰﾀ入力!AP28) -> 0 | CN8: =SUM(P8:CM8) -> 0
I9: 開閉店業務 | K9: PLAN | L9: =CHOOSE($CA$1,ﾃﾞｰﾀ入力!W14,ﾃﾞｰﾀ入力!W17,ﾃﾞｰﾀ入力!W20,ﾃﾞｰﾀ入力!W23,ﾃﾞｰﾀ入力!W26,ﾃﾞｰﾀ入力!W29) -> 0 | P9: =CHOOSE($CA$1,ﾃﾞｰﾀ入力!X14,ﾃﾞｰﾀ入力!X17,ﾃﾞｰﾀ入力!X20,ﾃﾞｰﾀ入力!X23,ﾃﾞｰﾀ入力!X26,ﾃﾞｰﾀ入力!X29) -> 0 | T9: =CHOOSE($CA$1,ﾃﾞｰﾀ入力!Y14,ﾃﾞｰﾀ入力!Y17,ﾃﾞｰﾀ入力!Y20,ﾃﾞｰﾀ入力!Y23,ﾃﾞｰﾀ入力!Y26,ﾃﾞｰﾀ入力!Y29) -> 0 | X9: =CHOOSE($CA$1,ﾃﾞｰﾀ入力!Z14,ﾃﾞｰﾀ入力!Z17,ﾃﾞｰﾀ入力!Z20,ﾃﾞｰﾀ入力!Z23,ﾃﾞｰﾀ入力!Z26,ﾃﾞｰﾀ入力!Z29) -> 0 | AB9: =CHOOSE($CA$1,ﾃﾞｰﾀ入力!AA14,ﾃﾞｰﾀ入力!AA17,ﾃﾞｰﾀ入力!AA20,ﾃﾞｰﾀ入力!AA23,ﾃﾞｰﾀ入力!AA26,ﾃﾞｰﾀ入力!AA29) -> 0 | AF9: =CHOOSE($CA$1,ﾃﾞｰﾀ入力!AB14,ﾃﾞｰﾀ入力!AB17,ﾃﾞｰﾀ入力!AB20,ﾃﾞｰﾀ入力!AB23,ﾃﾞｰﾀ入力!AB26,ﾃﾞｰﾀ入力!AB29) -> 0 | AJ9: =CHOOSE($CA$1,ﾃﾞｰﾀ入力!AC14,ﾃﾞｰﾀ入力!AC17,ﾃﾞｰﾀ入力!AC20,ﾃﾞｰﾀ入力!AC23,ﾃﾞｰﾀ入力!AC26,ﾃﾞｰﾀ入力!AC29) -> 0 | AN9: =CHOOSE($CA$1,ﾃﾞｰﾀ入力!AD14,ﾃﾞｰﾀ入力!AD17,ﾃﾞｰﾀ入力!AD20,ﾃﾞｰﾀ入力!AD23,ﾃﾞｰﾀ入力!AD26,ﾃﾞｰﾀ入力!AD29) -> 0 | AR9: =CHOOSE($CA$1,ﾃﾞｰﾀ入力!AE14,ﾃﾞｰﾀ入力!AE17,ﾃﾞｰﾀ入力!AE20,ﾃﾞｰﾀ入力!AE23,ﾃﾞｰﾀ入力!AE26,ﾃﾞｰﾀ入力!AE29) -> 0 | AV9: =CHOOSE($CA$1,ﾃﾞｰﾀ入力!AF14,ﾃﾞｰﾀ入力!AF17,ﾃﾞｰﾀ入力!AF20,ﾃﾞｰﾀ入力!AF23,ﾃﾞｰﾀ入力!AF26,ﾃﾞｰﾀ入力!AF29) -> 0 | AZ9: =CHOOSE($CA$1,ﾃﾞｰﾀ入力!AG14,ﾃﾞｰﾀ入力!AG17,ﾃﾞｰﾀ入力!AG20,ﾃﾞｰﾀ入力!AG23,ﾃﾞｰﾀ入力!AG26,ﾃﾞｰﾀ入力!AG29) -> 0 | BD9: =CHOOSE($CA$1,ﾃﾞｰﾀ入力!AH14,ﾃﾞｰﾀ入力!AH17,ﾃﾞｰﾀ入力!AH20,ﾃﾞｰﾀ入力!AH23,ﾃﾞｰﾀ入力!AH26,ﾃﾞｰﾀ入力!AH29) -> 0 | BH9: =CHOOSE($CA$1,ﾃﾞｰﾀ入力!AI14,ﾃﾞｰﾀ入力!AI17,ﾃﾞｰﾀ入力!AI20,ﾃﾞｰﾀ入力!AI23,ﾃﾞｰﾀ入力!AI26,ﾃﾞｰﾀ入力!AI29) -> 0 | BL9: =CHOOSE($CA$1,ﾃﾞｰﾀ入力!AJ14,ﾃﾞｰﾀ入力!AJ17,ﾃﾞｰﾀ入力!AJ20,ﾃﾞｰﾀ入力!AJ23,ﾃﾞｰﾀ入力!AJ26,ﾃﾞｰﾀ入力!AJ29) -> 0 | BP9: =CHOOSE($CA$1,ﾃﾞｰﾀ入力!AK14,ﾃﾞｰﾀ入力!AK17,ﾃﾞｰﾀ入力!AK20,ﾃﾞｰﾀ入力!AK23,ﾃﾞｰﾀ入力!AK26,ﾃﾞｰﾀ入力!AK29) -> 0 | BT9: =CHOOSE($CA$1,ﾃﾞｰﾀ入力!AL14,ﾃﾞｰﾀ入力!AL17,ﾃﾞｰﾀ入力!AL20,ﾃﾞｰﾀ入力!AL23,ﾃﾞｰﾀ入力!AL26,ﾃﾞｰﾀ入力!AL29) -> 0 | BX9: =CHOOSE($CA$1,ﾃﾞｰﾀ入力!AM14,ﾃﾞｰﾀ入力!AM17,ﾃﾞｰﾀ入力!AM20,ﾃﾞｰﾀ入力!AM23,ﾃﾞｰﾀ入力!AM26,ﾃﾞｰﾀ入力!AM29) -> 0 | CB9: =CHOOSE($CA$1,ﾃﾞｰﾀ入力!AN14,ﾃﾞｰﾀ入力!AN17,ﾃﾞｰﾀ入力!AN20,ﾃﾞｰﾀ入力!AN23,ﾃﾞｰﾀ入力!AN26,ﾃﾞｰﾀ入力!AN29) -> 0 | CF9: =CHOOSE($CA$1,ﾃﾞｰﾀ入力!AO14,ﾃﾞｰﾀ入力!AO17,ﾃﾞｰﾀ入力!AO20,ﾃﾞｰﾀ入力!AO23,ﾃﾞｰﾀ入力!AO26,ﾃﾞｰﾀ入力!AO29) -> 0 | CJ9: =CHOOSE($CA$1,ﾃﾞｰﾀ入力!AP14,ﾃﾞｰﾀ入力!AP17,ﾃﾞｰﾀ入力!AP20,ﾃﾞｰﾀ入力!AP23,ﾃﾞｰﾀ入力!AP26,ﾃﾞｰﾀ入力!AP29) -> 0 | CN9: =SUM(P9:CM9) -> 0
I10: 入金・発注・書類 | K10: PLAN | L10: =CHOOSE($CA$1,ﾃﾞｰﾀ入力!W15,ﾃﾞｰﾀ入力!W18,ﾃﾞｰﾀ入力!W21,ﾃﾞｰﾀ入力!W24,ﾃﾞｰﾀ入力!W27,ﾃﾞｰﾀ入力!W30) -> 0 | P10: =CHOOSE($CA$1,ﾃﾞｰﾀ入力!X15,ﾃﾞｰﾀ入力!X18,ﾃﾞｰﾀ入力!X21,ﾃﾞｰﾀ入力!X24,ﾃﾞｰﾀ入力!X27,ﾃﾞｰﾀ入力!X30) -> 0 | T10: =CHOOSE($CA$1,ﾃﾞｰﾀ入力!Y15,ﾃﾞｰﾀ入力!Y18,ﾃﾞｰﾀ入力!Y21,ﾃﾞｰﾀ入力!Y24,ﾃﾞｰﾀ入力!Y27,ﾃﾞｰﾀ入力!Y30) -> 0 | X10: =CHOOSE($CA$1,ﾃﾞｰﾀ入力!Z15,ﾃﾞｰﾀ入力!Z18,ﾃﾞｰﾀ入力!Z21,ﾃﾞｰﾀ入力!Z24,ﾃﾞｰﾀ入力!Z27,ﾃﾞｰﾀ入力!Z30) -> 0 | AB10: =CHOOSE($CA$1,ﾃﾞｰﾀ入力!AA15,ﾃﾞｰﾀ入力!AA18,ﾃﾞｰﾀ入力!AA21,ﾃﾞｰﾀ入力!AA24,ﾃﾞｰﾀ入力!AA27,ﾃﾞｰﾀ入力!AA30) -> 0 | AF10: =CHOOSE($CA$1,ﾃﾞｰﾀ入力!AB15,ﾃﾞｰﾀ入力!AB18,ﾃﾞｰﾀ入力!AB21,ﾃﾞｰﾀ入力!AB24,ﾃﾞｰﾀ入力!AB27,ﾃﾞｰﾀ入力!AB30) -> 0 | AJ10: =CHOOSE($CA$1,ﾃﾞｰﾀ入力!AC15,ﾃﾞｰﾀ入力!AC18,ﾃﾞｰﾀ入力!AC21,ﾃﾞｰﾀ入力!AC24,ﾃﾞｰﾀ入力!AC27,ﾃﾞｰﾀ入力!AC30) -> 0 | AN10: =CHOOSE($CA$1,ﾃﾞｰﾀ入力!AD15,ﾃﾞｰﾀ入力!AD18,ﾃﾞｰﾀ入力!AD21,ﾃﾞｰﾀ入力!AD24,ﾃﾞｰﾀ入力!AD27,ﾃﾞｰﾀ入力!AD30) -> 0 | AR10: =CHOOSE($CA$1,ﾃﾞｰﾀ入力!AE15,ﾃﾞｰﾀ入力!AE18,ﾃﾞｰﾀ入力!AE21,ﾃﾞｰﾀ入力!AE24,ﾃﾞｰﾀ入力!AE27,ﾃﾞｰﾀ入力!AE30) -> 0 | AV10: =CHOOSE($CA$1,ﾃﾞｰﾀ入力!AF15,ﾃﾞｰﾀ入力!AF18,ﾃﾞｰﾀ入力!AF21,ﾃﾞｰﾀ入力!AF24,ﾃﾞｰﾀ入力!AF27,ﾃﾞｰﾀ入力!AF30) -> 0 | AZ10: =CHOOSE($CA$1,ﾃﾞｰﾀ入力!AG15,ﾃﾞｰﾀ入力!AG18,ﾃﾞｰﾀ入力!AG21,ﾃﾞｰﾀ入力!AG24,ﾃﾞｰﾀ入力!AG27,ﾃﾞｰﾀ入力!AG30) -> 0 | BD10: =CHOOSE($CA$1,ﾃﾞｰﾀ入力!AH15,ﾃﾞｰﾀ入力!AH18,ﾃﾞｰﾀ入力!AH21,ﾃﾞｰﾀ入力!AH24,ﾃﾞｰﾀ入力!AH27,ﾃﾞｰﾀ入力!AH30) -> 0 | BH10: =CHOOSE($CA$1,ﾃﾞｰﾀ入力!AI15,ﾃﾞｰﾀ入力!AI18,ﾃﾞｰﾀ入力!AI21,ﾃﾞｰﾀ入力!AI24,ﾃﾞｰﾀ入力!AI27,ﾃﾞｰﾀ入力!AI30) -> 0 | BL10: =CHOOSE($CA$1,ﾃﾞｰﾀ入力!AJ15,ﾃﾞｰﾀ入力!AJ18,ﾃﾞｰﾀ入力!AJ21,ﾃﾞｰﾀ入力!AJ24,ﾃﾞｰﾀ入力!AJ27,ﾃﾞｰﾀ入力!AJ30) -> 0 | BP10: =CHOOSE($CA$1,ﾃﾞｰﾀ入力!AK15,ﾃﾞｰﾀ入力!AK18,ﾃﾞｰﾀ入力!AK21,ﾃﾞｰﾀ入力!AK24,ﾃﾞｰﾀ入力!AK27,ﾃﾞｰﾀ入力!AK30) -> 0 | BT10: =CHOOSE($CA$1,ﾃﾞｰﾀ入力!AL15,ﾃﾞｰﾀ入力!AL18,ﾃﾞｰﾀ入力!AL21,ﾃﾞｰﾀ入力!AL24,ﾃﾞｰﾀ入力!AL27,ﾃﾞｰﾀ入力!AL30) -> 0 | BX10: =CHOOSE($CA$1,ﾃﾞｰﾀ入力!AM15,ﾃﾞｰﾀ入力!AM18,ﾃﾞｰﾀ入力!AM21,ﾃﾞｰﾀ入力!AM24,ﾃﾞｰﾀ入力!AM27,ﾃﾞｰﾀ入力!AM30) -> 0 | CB10: =CHOOSE($CA$1,ﾃﾞｰﾀ入力!AN15,ﾃﾞｰﾀ入力!AN18,ﾃﾞｰﾀ入力!AN21,ﾃﾞｰﾀ入力!AN24,ﾃﾞｰﾀ入力!AN27,ﾃﾞｰﾀ入力!AN30) -> 0 | CF10: =CHOOSE($CA$1,ﾃﾞｰﾀ入力!AO15,ﾃﾞｰﾀ入力!AO18,ﾃﾞｰﾀ入力!AO21,ﾃﾞｰﾀ入力!AO24,ﾃﾞｰﾀ入力!AO27,ﾃﾞｰﾀ入力!AO30) -> 0 | CJ10: =CHOOSE($CA$1,ﾃﾞｰﾀ入力!AP15,ﾃﾞｰﾀ入力!AP18,ﾃﾞｰﾀ入力!AP21,ﾃﾞｰﾀ入力!AP24,ﾃﾞｰﾀ入力!AP27,ﾃﾞｰﾀ入力!AP30) -> 0 | CN10: =SUM(P10:CM10) -> 0
I11: 合計時間 | K11: PLAN | L11: =L7+L8+L9+L10 -> 0 | P11: =P7+P8+P9+P10 -> 0 | T11: =T7+T8+T9+T10 -> 0 | X11: =X7+X8+X9+X10 -> 2 | AB11: =AB7+AB8+AB9+AB10 -> 2 | AF11: =AF7+AF8+AF9+AF10 -> 2 | AJ11: =AJ7+AJ8+AJ9+AJ10 -> 2 | AN11: =AN7+AN8+AN9+AN10 -> 4 | AR11: =AR7+AR8+AR9+AR10 -> 4 | AV11: =AV7+AV8+AV9+AV10 -> 4 | AZ11: =AZ7+AZ8+AZ9+AZ10 -> 4 | BD11: =BD7+BD8+BD9+BD10 -> 4 | BH11: =BH7+BH8+BH9+BH10 -> 3 | BL11: =BL7+BL8+BL9+BL10 -> 2 | BP11: =BP7+BP8+BP9+BP10 -> 2 | BT11: =BT7+BT8+BT9+BT10 -> 2 | BX11: =BX7+BX8+BX9+BX10 -> 2 | CB11: =CB7+CB8+CB9+CB10 -> 0 | CF11: =CF7+CF8+CF9+CF10 -> 0 | CJ11: =CJ7+CJ8+CJ9+CJ10 -> 0 | CN11: =SUM(P11:CM11) -> 39 | CP11: =CN7+CN9+CN10 -> 39
L12: 5 | M12: 5.25 | N12: 5.5 | O12: 5.75 | P12: 6 | Q12: 6.25 | R12: 6.5 | S12: 6.75 | T12: 7 | U12: 7.25 | V12: 7.5 | W12: 7.75 | X12: 8 | Y12: 8.25 | Z12: 8.5 | AA12: 8.75 | AB12: 9 | AC12: 9.25 | AD12: 9.5 | AE12: 9.75 | AF12: 10 | AG12: 10.25 | AH12: 10.5 | AI12: 10.75 | AJ12: 11 | AK12: 11.25 | AL12: 11.5 | AM12: 11.75 | AN12: 12 | AO12: 12.25 | AP12: 12.5 | AQ12: 12.75 | AR12: 13 | AS12: 13.25 | AT12: 13.5 | AU12: 13.75 | AV12: 14 | AW12: 14.25 | AX12: 14.5 | AY12: 14.75 | AZ12: 15 | BA12: 15.25 | BB12: 15.5 | BC12: 15.75 | BD12: 16 | BE12: 16.25 | BF12: 16.5 | BG12: 16.75 | BH12: 17 | BI12: 17.25 | BJ12: 17.5 | BK12: 17.75 | BL12: 18 | BM12: 18.25 | BN12: 18.5 | BO12: 18.75 | BP12: 19 | BQ12: 19.25 | BR12: 19.5 | BS12: 19.75 | BT12: 20 | BU12: 20.25 | BV12: 20.5 | BW12: 20.75 | BX12: 21 | BY12: 21.25 | BZ12: 21.5 | CA12: 21.75 | CB12: 22 | CC12: 22.25 | CD12: 22.5 | CE12: 22.75 | CF12: 23 | CG12: 23.25 | CH12: 23.5 | CI12: 23.75 | CJ12: 24 | CK12: 24.25 | CL12: 24.5 | CM12: 24.75
C13: 希望時間 | D13: 入店 | E13: 退店 | F13: 予定給与 | G13: 予定交通費 | H13: NO. | I13: STAFF | J13: 勤務時間 | L13: 0.20833333 | P13: 0.25 | T13: 7:00 | X13: 8:00 | AB13: 9:00 | AF13: 10:00 | AJ13: 11:00 | AN13: 12:00 | AR13: 13:00 | AV13: 14:00 | AZ13: 15:00 | BD13: 16:00 | BH13: 17:00 | BL13: 18:00 | BP13: 19:00 | BT13: 20:00 | BX13: 21:00 | CB13: 22:00 | CF13: 23:00 | CJ13: 24:00 | CN13: 勤務 | CP13: 労働 | CR13: 超勤 | CS13: 深夜 | CT13: 残深 | CU13: 給与 | CV13: 時給 | CW13: 交通費
A14: 1 | B14: =ｼﾌﾄ原本!C5 -> K.M | C14: =ｼﾌﾄ原本!E5 -> F | D14: =IF(COUNTIF($H$14:$H$30,1),VLOOKUP(1,$H$14:$CU$30,3,FALSE),0) -> 12 | E14: =IF(COUNTIF($H$14:$H$30,1),VLOOKUP(1,$H$14:$CU$30,4,FALSE),0) -> 22.75 | F14: =IF(COUNTIF($H$14:$H$30,1),VLOOKUP(1,$H$14:$CU$30,92,FALSE),0) -> 20875 | G14: =IF(COUNTIF($H$14:$H$30,1),VLOOKUP(1,$H$14:$CW$30,94,FALSE),0) -> 1 | H14: 6 | I14: =IF(H14=0,0,LOOKUP(H14,ﾃﾞｰﾀ入力!$C$3:'ﾃﾞｰﾀ入力'!$C$40,ﾃﾞｰﾀ入力!$D$3:'ﾃﾞｰﾀ入力'!$D$40)) -> S.M | J14: 6.75 | K14: 16 | L14: =IF(AND(L12>=$J$14,L12<$K$14),"*",0) -> 0 | M14: =IF(AND(M12>=$J$14,M12<$K$14),"*",0) -> 0 | N14: =IF(AND(N12>=$J$14,N12<$K$14),"*",0) -> 0 | O14: =IF(AND(O12>=$J$14,O12<$K$14),"*",0) -> 0 | P14: =IF(AND(P12>=$J$14,P12<$K$14),"*",0) -> 0 | Q14: =IF(AND(Q12>=$J$14,Q12<$K$14),"*",0) -> 0 | R14: =IF(AND(R12>=$J$14,R12<$K$14),"*",0) -> 0 | S14: =IF(AND(S12>=$J$14,S12<$K$14),"*",0) -> * | ... CM14: =IF(AND(CM12>=$J$14,CM12<$K$14),"*",0) -> 0 | CN14: =(80-COUNT(L14:CM14))/4 -> 9.25 | CP14: =IF(CN14=0,0,LOOKUP(CN14,ﾃﾞｰﾀ入力!$AR$13:'ﾃﾞｰﾀ入力'!$AR$34,ﾃﾞｰﾀ入力!$AS$13:'ﾃﾞｰﾀ入力'!$AS$34)) -> 8 | CR14: =IF(CP14>8,CP14-8,0) -> 0 | CS14: =IF(CB14="*",(12-COUNT(CB14:CM14))/4,0) -> 0 | CT14: =IF(CR14>CS14,CS14,CR14) -> 0 | CU14: =CV14*CP14+(CV14*0.25*CR14)+(CV14*0.25*CS14)+(CV14*CT14*0.5) -> 9952 | CV14: =IF(H14=0,0,LOOKUP(H14,ﾃﾞｰﾀ入力!$C$3:'ﾃﾞｰﾀ入力'!$C$52,ﾃﾞｰﾀ入力!$E$3:'ﾃﾞｰﾀ入力'!$E$51)) -> 1244 | CW14: =IF(H14=0,0,LOOKUP(H14,ﾃﾞｰﾀ入力!$C$3:'ﾃﾞｰﾀ入力'!$C$52,ﾃﾞｰﾀ入力!$F$3:'ﾃﾞｰﾀ入力'!$F$51)) -> 1050
A15: =A14+1 -> 2 | B15: =ｼﾌﾄ原本!C6 -> S.S | C15: =ｼﾌﾄ原本!E6 -> F | D15: =IF(COUNTIF($H$14:$H$30,2),VLOOKUP(2,$H$14:$CU$30,3,FALSE),0) -> 11 | E15: =IF(COUNTIF($H$14:$H$30,2),VLOOKUP(2,$H$14:$CU$30,4,FALSE),0) -> 22.75 | F15: =IF(COUNTIF($H$14:$H$30,2),VLOOKUP(2,$H$14:$CU$30,92,FALSE),0) -> 17531.25 | G15: =IF(COUNTIF($H$14:$H$30,2),VLOOKUP(2,$H$14:$CW$30,94,FALSE),0) -> 1 | H15: 8 | I15: =IF(H15=0,0,LOOKUP(H15,ﾃﾞｰﾀ入力!$C$3:'ﾃﾞｰﾀ入力'!$C$40,ﾃﾞｰﾀ入力!$D$3:'ﾃﾞｰﾀ入力'!$D$40)) -> M.K | J15: 7 | K15: 16 | L15: =IF(AND(L12>=$J$15,L12<$K$15),"*",0) -> 0 | M15: =IF(AND(M12>=$J$15,M12<$K$15),"*",0) -> 0 | N15: =IF(AND(N12>=$J$15,N12<$K$15),"*",0) -> 0 | O15: =IF(AND(O12>=$J$15,O12<$K$15),"*",0) -> 0 | P15: =IF(AND(P12>=$J$15,P12<$K$15),"*",0) -> 0 | Q15: =IF(AND(Q12>=$J$15,Q12<$K$15),"*",0) -> 0 | R15: =IF(AND(R12>=$J$15,R12<$K$15),"*",0) -> 0 | S15: =IF(AND(S12>=$J$15,S12<$K$15),"*",0) -> 0 | ... CM15: =IF(AND(CM12>=$J$15,CM12<$K$15),"*",0) -> 0 | CN15: =(80-COUNT(L15:CM15))/4 -> 9 | CP15: =IF(CN15=0,0,LOOKUP(CN15,ﾃﾞｰﾀ入力!$AR$13:'ﾃﾞｰﾀ入力'!$AR$34,ﾃﾞｰﾀ入力!$AS$13:'ﾃﾞｰﾀ入力'!$AS$34)) -> 8 | CR15: =IF(CP15>8,CP15-8,0) -> 0 | CS15: =IF(CB15="*",(12-COUNT(CB15:CM15))/4,0) -> 0 | CT15: =IF(CR15>CS15,CS15,CR15) -> 0 | CU15: =CV15*CP15+(CV15*0.25*CR15)+(CV15*0.25*CS15)+(CV15*CT15*0.5) -> 9808 | CV15: =IF(H15=0,0,LOOKUP(H15,ﾃﾞｰﾀ入力!$C$3:'ﾃﾞｰﾀ入力'!$C$52,ﾃﾞｰﾀ入力!$E$3:'ﾃﾞｰﾀ入力'!$E$51)) -> 1226 | CW15: =IF(H15=0,0,LOOKUP(H15,ﾃﾞｰﾀ入力!$C$3:'ﾃﾞｰﾀ入力'!$C$52,ﾃﾞｰﾀ入力!$F$3:'ﾃﾞｰﾀ入力'!$F$51)) -> 1430
A16: =A15+1 -> 3 | B16: =ｼﾌﾄ原本!C7 -> Y.I | C16: =ｼﾌﾄ原本!E7 -> 0 | D16: =IF(COUNTIF($H$14:$H$30,3),VLOOKUP(3,$H$14:$CU$30,3,FALSE),0) -> 0 | E16: =IF(COUNTIF($H$14:$H$30,3),VLOOKUP(3,$H$14:$CU$30,4,FALSE),0) -> 0 | F16: =IF(COUNTIF($H$14:$H$30,3),VLOOKUP(3,$H$14:$CU$30,92,FALSE),0) -> 0 | G16: =IF(COUNTIF($H$14:$H$30,3),VLOOKUP(3,$H$14:$CW$30,94,FALSE),0) -> 0 | H16: 13 | I16: =IF(H16=0,0,LOOKUP(H16,ﾃﾞｰﾀ入力!$C$3:'ﾃﾞｰﾀ入力'!$C$40,ﾃﾞｰﾀ入力!$D$3:'ﾃﾞｰﾀ入力'!$D$40)) -> T.R | J16: 10 | K16: 20 | L16: =IF(AND(L12>=$J$16,L12<$K$16),"*",0) -> 0 | M16: =IF(AND(M12>=$J$16,M12<$K$16),"*",0) -> 0 | N16: =IF(AND(N12>=$J$16,N12<$K$16),"*",0) -> 0 | O16: =IF(AND(O12>=$J$16,O12<$K$16),"*",0) -> 0 | P16: =IF(AND(P12>=$J$16,P12<$K$16),"*",0) -> 0 | Q16: =IF(AND(Q12>=$J$16,Q12<$K$16),"*",0) -> 0 | R16: =IF(AND(R12>=$J$16,R12<$K$16),"*",0) -> 0 | S16: =IF(AND(S12>=$J$16,S12<$K$16),"*",0) -> 0 | ... CM16: =IF(AND(CM12>=$J$16,CM12<$K$16),"*",0) -> 0 | CN16: =(80-COUNT(L16:CM16))/4 -> 10 | CP16: =IF(CN16=0,0,LOOKUP(CN16,ﾃﾞｰﾀ入力!$AR$13:'ﾃﾞｰﾀ入力'!$AR$34,ﾃﾞｰﾀ入力!$AS$13:'ﾃﾞｰﾀ入力'!$AS$34)) -> 9 | CR16: =IF(CP16>8,CP16-8,0) -> 1 | CS16: =IF(CB16="*",(12-COUNT(CB16:CM16))/4,0) -> 0 | CT16: =IF(CR16>CS16,CS16,CR16) -> 0 | CU16: =CV16*CP16+(CV16*0.25*CR16)+(CV16*0.25*CS16)+(CV16*CT16*0.5) -> 11340.5 | CV16: =IF(H16=0,0,LOOKUP(H16,ﾃﾞｰﾀ入力!$C$3:'ﾃﾞｰﾀ入力'!$C$52,ﾃﾞｰﾀ入力!$E$3:'ﾃﾞｰﾀ入力'!$E$51)) -> 1226 | CW16: =IF(H16=0,0,LOOKUP(H16,ﾃﾞｰﾀ入力!$C$3:'ﾃﾞｰﾀ入力'!$C$52,ﾃﾞｰﾀ入力!$F$3:'ﾃﾞｰﾀ入力'!$F$51)) -> 900
A17: =A16+1 -> 4 | B17: =ｼﾌﾄ原本!C8 -> I.Y | C17: =ｼﾌﾄ原本!E8 -> X | D17: =IF(COUNTIF($H$14:$H$30,4),VLOOKUP(4,$H$14:$CU$30,3,FALSE),0) -> 18 | E17: =IF(COUNTIF($H$14:$H$30,4),VLOOKUP(4,$H$14:$CU$30,4,FALSE),0) -> 22.75 | F17: =IF(COUNTIF($H$14:$H$30,4),VLOOKUP(4,$H$14:$CU$30,92,FALSE),0) -> 6140.625 | G17: =IF(COUNTIF($H$14:$H$30,4),VLOOKUP(4,$H$14:$CW$30,94,FALSE),0) -> 962 | H17: 15 | I17: =IF(H17=0,0,LOOKUP(H17,ﾃﾞｰﾀ入力!$C$3:'ﾃﾞｰﾀ入力'!$C$40,ﾃﾞｰﾀ入力!$D$3:'ﾃﾞｰﾀ入力'!$D$40)) -> W.M | L17: =IF(AND(L12>=$J$17,L12<$K$17),"*",0) -> 0 | M17: =IF(AND(M12>=$J$17,M12<$K$17),"*",0) -> 0 | N17: =IF(AND(N12>=$J$17,N12<$K$17),"*",0) -> 0 | O17: =IF(AND(O12>=$J$17,O12<$K$17),"*",0) -> 0 | P17: =IF(AND(P12>=$J$17,P12<$K$17),"*",0) -> 0 | Q17: =IF(AND(Q12>=$J$17,Q12<$K$17),"*",0) -> 0 | R17: =IF(AND(R12>=$J$17,R12<$K$17),"*",0) -> 0 | S17: =IF(AND(S12>=$J$17,S12<$K$17),"*",0) -> 0 | ... CM17: =IF(AND(CM12>=$J$17,CM12<$K$17),"*",0) -> 0 | CN17: =(80-COUNT(L17:CM17))/4 -> 0 | CP17: =IF(CN17=0,0,LOOKUP(CN17,ﾃﾞｰﾀ入力!$AR$13:'ﾃﾞｰﾀ入力'!$AR$34,ﾃﾞｰﾀ入力!$AS$13:'ﾃﾞｰﾀ入力'!$AS$34)) -> 0 | CR17: =IF(CP17>8,CP17-8,0) -> 0 | CS17: =IF(CB17="*",(12-COUNT(CB17:CM17))/4,0) -> 0 | CT17: =IF(CR17>CS17,CS17,CR17) -> 0 | CU17: =CV17*CP17+(CV17*0.25*CR17)+(CV17*0.25*CS17)+(CV17*CT17*0.5) -> 0 | CV17: =IF(H17=0,0,LOOKUP(H17,ﾃﾞｰﾀ入力!$C$3:'ﾃﾞｰﾀ入力'!$C$52,ﾃﾞｰﾀ入力!$E$3:'ﾃﾞｰﾀ入力'!$E$51)) -> 1226 | CW17: =IF(H17=0,0,LOOKUP(H17,ﾃﾞｰﾀ入力!$C$3:'ﾃﾞｰﾀ入力'!$C$52,ﾃﾞｰﾀ入力!$F$3:'ﾃﾞｰﾀ入力'!$F$51)) -> 376
A18: =A17+1 -> 5 | B18: =ｼﾌﾄ原本!C9 -> S.S | C18: =ｼﾌﾄ原本!E9 -> X | D18: =IF(COUNTIF($H$14:$H$30,5),VLOOKUP(5,$H$14:$CU$30,3,FALSE),0) -> 0 | E18: =IF(COUNTIF($H$14:$H$30,5),VLOOKUP(5,$H$14:$CU$30,4,FALSE),0) -> 0 | F18: =IF(COUNTIF($H$14:$H$30,5),VLOOKUP(5,$H$14:$CU$30,92,FALSE),0) -> 0 | G18: =IF(COUNTIF($H$14:$H$30,5),VLOOKUP(5,$H$14:$CW$30,94,FALSE),0) -> 0 | H18: 1 | I18: =IF(H18=0,0,LOOKUP(H18,ﾃﾞｰﾀ入力!$C$3:'ﾃﾞｰﾀ入力'!$C$40,ﾃﾞｰﾀ入力!$D$3:'ﾃﾞｰﾀ入力'!$D$40)) -> K.M | J18: 12 | K18: 22.75 | L18: =IF(AND(L12>=$J$18,L12<$K$18),"*",0) -> 0 | M18: =IF(AND(M12>=$J$18,M12<$K$18),"*",0) -> 0 | N18: =IF(AND(N12>=$J$18,N12<$K$18),"*",0) -> 0 | O18: =IF(AND(O12>=$J$18,O12<$K$18),"*",0) -> 0 | P18: =IF(AND(P12>=$J$18,P12<$K$18),"*",0) -> 0 | Q18: =IF(AND(Q12>=$J$18,Q12<$K$18),"*",0) -> 0 | R18: =IF(AND(R12>=$J$18,R12<$K$18),"*",0) -> 0 | S18: =IF(AND(S12>=$J$18,S12<$K$18),"*",0) -> 0 | ... CM18: =IF(AND(CM12>=$J$18,CM12<$K$18),"*",0) -> 0 | CN18: =(80-COUNT(L18:CM18))/4 -> 10.75 | CP18: =IF(CN18=0,0,LOOKUP(CN18,ﾃﾞｰﾀ入力!$AR$13:'ﾃﾞｰﾀ入力'!$AR$34,ﾃﾞｰﾀ入力!$AS$13:'ﾃﾞｰﾀ入力'!$AS$34)) -> 9.5 | CR18: =IF(CP18>8,CP18-8,0) -> 1.5 | CS18: =IF(CB18="*",(12-COUNT(CB18:CM18))/4,0) -> 0.75 | CT18: =IF(CR18>CS18,CS18,CR18) -> 0.75 | CU18: =CV18*CP18+(CV18*0.25*CR18)+(CV18*0.25*CS18)+(CV18*CT18*0.5) -> 20875 | CV18: =IF(H18=0,0,LOOKUP(H18,ﾃﾞｰﾀ入力!$C$3:'ﾃﾞｰﾀ入力'!$C$52,ﾃﾞｰﾀ入力!$E$3:'ﾃﾞｰﾀ入力'!$E$51)) -> 2000 | CW18: =IF(H18=0,0,LOOKUP(H18,ﾃﾞｰﾀ入力!$C$3:'ﾃﾞｰﾀ入力'!$C$52,ﾃﾞｰﾀ入力!$F$3:'ﾃﾞｰﾀ入力'!$F$51)) -> 1
A19: =A18+1 -> 6 | B19: =ｼﾌﾄ原本!C10 -> S.M | C19: =ｼﾌﾄ原本!E10 -> O-16 | D19: =IF(COUNTIF($H$14:$H$30,6),VLOOKUP(6,$H$14:$CU$30,3,FALSE),0) -> 6.75 | E19: =IF(COUNTIF($H$14:$H$30,6),VLOOKUP(6,$H$14:$CU$30,4,FALSE),0) -> 16 | F19: =IF(COUNTIF($H$14:$H$30,6),VLOOKUP(6,$H$14:$CU$30,92,FALSE),0) -> 9952 | G19: =IF(COUNTIF($H$14:$H$30,6),VLOOKUP(6,$H$14:$CW$30,94,FALSE),0) -> 1050 | H19: 21 | I19: =IF(H19=0,0,LOOKUP(H19,ﾃﾞｰﾀ入力!$C$3:'ﾃﾞｰﾀ入力'!$C$40,ﾃﾞｰﾀ入力!$D$3:'ﾃﾞｰﾀ入力'!$D$40)) -> S.K | J19: 12 | K19: 17 | L19: =IF(AND(L12>=$J$19,L12<$K$19),"*",0) -> 0 | M19: =IF(AND(M12>=$J$19,M12<$K$19),"*",0) -> 0 | N19: =IF(AND(N12>=$J$19,N12<$K$19),"*",0) -> 0 | O19: =IF(AND(O12>=$J$19,O12<$K$19),"*",0) -> 0 | P19: =IF(AND(P12>=$J$19,P12<$K$19),"*",0) -> 0 | Q19: =IF(AND(Q12>=$J$19,Q12<$K$19),"*",0) -> 0 | R19: =IF(AND(R12>=$J$19,R12<$K$19),"*",0) -> 0 | S19: =IF(AND(S12>=$J$19,S12<$K$19),"*",0) -> 0 | ... CM19: =IF(AND(CM12>=$J$19,CM12<$K$19),"*",0) -> 0 | CN19: =(80-COUNT(L19:CM19))/4 -> 5 | CP19: =IF(CN19=0,0,LOOKUP(CN19,ﾃﾞｰﾀ入力!$AR$13:'ﾃﾞｰﾀ入力'!$AR$34,ﾃﾞｰﾀ入力!$AS$13:'ﾃﾞｰﾀ入力'!$AS$34)) -> 5 | CR19: =IF(CP19>8,CP19-8,0) -> 0 | CS19: =IF(CB19="*",(12-COUNT(CB19:CM19))/4,0) -> 0 | CT19: =IF(CR19>CS19,CS19,CR19) -> 0 | CU19: =CV19*CP19+(CV19*0.25*CR19)+(CV19*0.25*CS19)+(CV19*CT19*0.5) -> 6130 | CV19: =IF(H19=0,0,LOOKUP(H19,ﾃﾞｰﾀ入力!$C$3:'ﾃﾞｰﾀ入力'!$C$52,ﾃﾞｰﾀ入力!$E$3:'ﾃﾞｰﾀ入力'!$E$51)) -> 1226 | CW19: =IF(H19=0,0,LOOKUP(H19,ﾃﾞｰﾀ入力!$C$3:'ﾃﾞｰﾀ入力'!$C$52,ﾃﾞｰﾀ入力!$F$3:'ﾃﾞｰﾀ入力'!$F$51)) -> 682
A20: =A19+1 -> 7 | B20: =ｼﾌﾄ原本!C11 -> N.D | C20: =ｼﾌﾄ原本!E11 -> X | D20: =IF(COUNTIF($H$14:$H$30,7),VLOOKUP(7,$H$14:$CU$30,3,FALSE),0) -> 0 | E20: =IF(COUNTIF($H$14:$H$30,7),VLOOKUP(7,$H$14:$CU$30,4,FALSE),0) -> 0 | F20: =IF(COUNTIF($H$14:$H$30,7),VLOOKUP(7,$H$14:$CU$30,92,FALSE),0) -> 0 | G20: =IF(COUNTIF($H$14:$H$30,7),VLOOKUP(7,$H$14:$CW$30,94,FALSE),0) -> 0 | H20: 2 | I20: =IF(H20=0,0,LOOKUP(H20,ﾃﾞｰﾀ入力!$C$3:'ﾃﾞｰﾀ入力'!$C$40,ﾃﾞｰﾀ入力!$D$3:'ﾃﾞｰﾀ入力'!$D$40)) -> S.S | J20: 11 | K20: 22.75 | L20: =IF(AND(L12>=$J$20,L12<$K$20),"*",0) -> 0 | M20: =IF(AND(M12>=$J$20,M12<$K$20),"*",0) -> 0 | N20: =IF(AND(N12>=$J$20,N12<$K$20),"*",0) -> 0 | O20: =IF(AND(O12>=$J$20,O12<$K$20),"*",0) -> 0 | P20: =IF(AND(P12>=$J$20,P12<$K$20),"*",0) -> 0 | Q20: =IF(AND(Q12>=$J$20,Q12<$K$20),"*",0) -> 0 | R20: =IF(AND(R12>=$J$20,R12<$K$20),"*",0) -> 0 | S20: =IF(AND(S12>=$J$20,S12<$K$20),"*",0) -> 0 | ... CM20: =IF(AND(CM12>=$J$20,CM12<$K$20),"*",0) -> 0 | CN20: =(80-COUNT(L20:CM20))/4 -> 11.75 | CP20: =IF(CN20=0,0,LOOKUP(CN20,ﾃﾞｰﾀ入力!$AR$13:'ﾃﾞｰﾀ入力'!$AR$34,ﾃﾞｰﾀ入力!$AS$13:'ﾃﾞｰﾀ入力'!$AS$34)) -> 10.5 | CR20: =IF(CP20>8,CP20-8,0) -> 2.5 | CS20: =IF(CB20="*",(12-COUNT(CB20:CM20))/4,0) -> 0.75 | CT20: =IF(CR20>CS20,CS20,CR20) -> 0.75 | CU20: =CV20*CP20+(CV20*0.25*CR20)+(CV20*0.25*CS20)+(CV20*CT20*0.5) -> 17531.25 | CV20: =IF(H20=0,0,LOOKUP(H20,ﾃﾞｰﾀ入力!$C$3:'ﾃﾞｰﾀ入力'!$C$52,ﾃﾞｰﾀ入力!$E$3:'ﾃﾞｰﾀ入力'!$E$51)) -> 1500 | CW20: =IF(H20=0,0,LOOKUP(H20,ﾃﾞｰﾀ入力!$C$3:'ﾃﾞｰﾀ入力'!$C$52,ﾃﾞｰﾀ入力!$F$3:'ﾃﾞｰﾀ入力'!$F$51)) -> 1
A21: =A20+1 -> 8 | B21: =ｼﾌﾄ原本!C12 -> M.K | C21: =ｼﾌﾄ原本!E12 -> O-16 | D21: =IF(COUNTIF($H$14:$H$30,8),VLOOKUP(8,$H$14:$CU$30,3,FALSE),0) -> 7 | E21: =IF(COUNTIF($H$14:$H$30,8),VLOOKUP(8,$H$14:$CU$30,4,FALSE),0) -> 16 | F21: =IF(COUNTIF($H$14:$H$30,8),VLOOKUP(8,$H$14:$CU$30,92,FALSE),0) -> 9808 | G21: =IF(COUNTIF($H$14:$H$30,8),VLOOKUP(8,$H$14:$CW$30,94,FALSE),0) -> 1430 | H21: 4 | I21: =IF(H21=0,0,LOOKUP(H21,ﾃﾞｰﾀ入力!$C$3:'ﾃﾞｰﾀ入力'!$C$40,ﾃﾞｰﾀ入力!$D$3:'ﾃﾞｰﾀ入力'!$D$40)) -> I.Y | J21: 18 | K21: 22.75 | L21: =IF(AND(L12>=$J$21,L12<$K$21),"*",0) -> 0 | M21: =IF(AND(M12>=$J$21,M12<$K$21),"*",0) -> 0 | N21: =IF(AND(N12>=$J$21,N12<$K$21),"*",0) -> 0 | O21: =IF(AND(O12>=$J$21,O12<$K$21),"*",0) -> 0 | P21: =IF(AND(P12>=$J$21,P12<$K$21),"*",0) -> 0 | Q21: =IF(AND(Q12>=$J$21,Q12<$K$21),"*",0) -> 0 | R21: =IF(AND(R12>=$J$21,R12<$K$21),"*",0) -> 0 | S21: =IF(AND(S12>=$J$21,S12<$K$21),"*",0) -> 0 | ... CM21: =IF(AND(CM12>=$J$21,CM12<$K$21),"*",0) -> 0 | CN21: =(80-COUNT(L21:CM21))/4 -> 4.75 | CP21: =IF(CN21=0,0,LOOKUP(CN21,ﾃﾞｰﾀ入力!$AR$13:'ﾃﾞｰﾀ入力'!$AR$34,ﾃﾞｰﾀ入力!$AS$13:'ﾃﾞｰﾀ入力'!$AS$34)) -> 4.5 | CR21: =IF(CP21>8,CP21-8,0) -> 0 | CS21: =IF(CB21="*",(12-COUNT(CB21:CM21))/4,0) -> 0.75 | CT21: =IF(CR21>CS21,CS21,CR21) -> 0 | CU21: =CV21*CP21+(CV21*0.25*CR21)+(CV21*0.25*CS21)+(CV21*CT21*0.5) -> 6140.625 | CV21: =IF(H21=0,0,LOOKUP(H21,ﾃﾞｰﾀ入力!$C$3:'ﾃﾞｰﾀ入力'!$C$52,ﾃﾞｰﾀ入力!$E$3:'ﾃﾞｰﾀ入力'!$E$51)) -> 1310 | CW21: =IF(H21=0,0,LOOKUP(H21,ﾃﾞｰﾀ入力!$C$3:'ﾃﾞｰﾀ入力'!$C$52,ﾃﾞｰﾀ入力!$F$3:'ﾃﾞｰﾀ入力'!$F$51)) -> 962
A22: =A21+1 -> 9 | B22: =ｼﾌﾄ原本!C13 -> H.S | C22: =ｼﾌﾄ原本!E13 -> X | D22: =IF(COUNTIF($H$14:$H$30,9),VLOOKUP(9,$H$14:$CU$30,3,FALSE),0) -> 0 | E22: =IF(COUNTIF($H$14:$H$30,9),VLOOKUP(9,$H$14:$CU$30,4,FALSE),0) -> 0 | F22: =IF(COUNTIF($H$14:$H$30,9),VLOOKUP(9,$H$14:$CU$30,92,FALSE),0) -> 0 | G22: =IF(COUNTIF($H$14:$H$30,9),VLOOKUP(9,$H$14:$CW$30,94,FALSE),0) -> 0 | I22: =IF(H22=0,0,LOOKUP(H22,ﾃﾞｰﾀ入力!$C$3:'ﾃﾞｰﾀ入力'!$C$40,ﾃﾞｰﾀ入力!$D$3:'ﾃﾞｰﾀ入力'!$D$40)) -> 0 | L22: =IF(AND(L12>=$J$22,L12<$K$22),"*",0) -> 0 | M22: =IF(AND(M12>=$J$22,M12<$K$22),"*",0) -> 0 | N22: =IF(AND(N12>=$J$22,N12<$K$22),"*",0) -> 0 | O22: =IF(AND(O12>=$J$22,O12<$K$22),"*",0) -> 0 | P22: =IF(AND(P12>=$J$22,P12<$K$22),"*",0) -> 0 | Q22: =IF(AND(Q12>=$J$22,Q12<$K$22),"*",0) -> 0 | R22: =IF(AND(R12>=$J$22,R12<$K$22),"*",0) -> 0 | S22: =IF(AND(S12>=$J$22,S12<$K$22),"*",0) -> 0 | ... CM22: =IF(AND(CM12>=$J$22,CM12<$K$22),"*",0) -> 0 | CN22: =(80-COUNT(L22:CM22))/4 -> 0 | CP22: =IF(CN22=0,0,LOOKUP(CN22,ﾃﾞｰﾀ入力!$AR$13:'ﾃﾞｰﾀ入力'!$AR$34,ﾃﾞｰﾀ入力!$AS$13:'ﾃﾞｰﾀ入力'!$AS$34)) -> 0 | CR22: =IF(CP22>8,CP22-8,0) -> 0 | CS22: =IF(CB22="*",(12-COUNT(CB22:CM22))/4,0) -> 0 | CT22: =IF(CR22>CS22,CS22,CR22) -> 0 | CU22: =CV22*CP22+(CV22*0.25*CR22)+(CV22*0.25*CS22)+(CV22*CT22*0.5) -> 0 | CV22: =IF(H22=0,0,LOOKUP(H22,ﾃﾞｰﾀ入力!$C$3:'ﾃﾞｰﾀ入力'!$C$52,ﾃﾞｰﾀ入力!$E$3:'ﾃﾞｰﾀ入力'!$E$51)) -> 0 | CW22: =IF(H22=0,0,LOOKUP(H22,ﾃﾞｰﾀ入力!$C$3:'ﾃﾞｰﾀ入力'!$C$52,ﾃﾞｰﾀ入力!$F$3:'ﾃﾞｰﾀ入力'!$F$51)) -> 0
A23: =A22+1 -> 10 | B23: =ｼﾌﾄ原本!C14 -> C.E | C23: =ｼﾌﾄ原本!E14 -> X | D23: =IF(COUNTIF($H$14:$H$30,10),VLOOKUP(10,$H$14:$CU$30,3,FALSE),0) -> 0 | E23: =IF(COUNTIF($H$14:$H$30,10),VLOOKUP(10,$H$14:$CU$30,4,FALSE),0) -> 0 | F23: =IF(COUNTIF($H$14:$H$30,10),VLOOKUP(10,$H$14:$CU$30,92,FALSE),0) -> 0 | G23: =IF(COUNTIF($H$14:$H$30,10),VLOOKUP(10,$H$14:$CW$30,94,FALSE),0) -> 0 | I23: =IF(H23=0,0,LOOKUP(H23,ﾃﾞｰﾀ入力!$C$3:'ﾃﾞｰﾀ入力'!$C$40,ﾃﾞｰﾀ入力!$D$3:'ﾃﾞｰﾀ入力'!$D$40)) -> 0 | L23: =IF(AND(L12>=$J$23,L12<$K$23),"*",0) -> 0 | M23: =IF(AND(M12>=$J$23,M12<$K$23),"*",0) -> 0 | N23: =IF(AND(N12>=$J$23,N12<$K$23),"*",0) -> 0 | O23: =IF(AND(O12>=$J$23,O12<$K$23),"*",0) -> 0 | P23: =IF(AND(P12>=$J$23,P12<$K$23),"*",0) -> 0 | Q23: =IF(AND(Q12>=$J$23,Q12<$K$23),"*",0) -> 0 | R23: =IF(AND(R12>=$J$23,R12<$K$23),"*",0) -> 0 | S23: =IF(AND(S12>=$J$23,S12<$K$23),"*",0) -> 0 | ... CM23: =IF(AND(CM12>=$J$23,CM12<$K$23),"*",0) -> 0 | CN23: =(80-COUNT(L23:CM23))/4 -> 0 | CP23: =IF(CN23=0,0,LOOKUP(CN23,ﾃﾞｰﾀ入力!$AR$13:'ﾃﾞｰﾀ入力'!$AR$34,ﾃﾞｰﾀ入力!$AS$13:'ﾃﾞｰﾀ入力'!$AS$34)) -> 0 | CR23: =IF(CP23>8,CP23-8,0) -> 0 | CS23: =IF(CB23="*",(12-COUNT(CB23:CM23))/4,0) -> 0 | CT23: =IF(CR23>CS23,CS23,CR23) -> 0 | CU23: =CV23*CP23+(CV23*0.25*CR23)+(CV23*0.25*CS23)+(CV23*CT23*0.5) -> 0 | CV23: =IF(H23=0,0,LOOKUP(H23,ﾃﾞｰﾀ入力!$C$3:'ﾃﾞｰﾀ入力'!$C$52,ﾃﾞｰﾀ入力!$E$3:'ﾃﾞｰﾀ入力'!$E$51)) -> 0 | CW23: =IF(H23=0,0,LOOKUP(H23,ﾃﾞｰﾀ入力!$C$3:'ﾃﾞｰﾀ入力'!$C$52,ﾃﾞｰﾀ入力!$F$3:'ﾃﾞｰﾀ入力'!$F$51)) -> 0
A24: =A23+1 -> 11 | B24: =ｼﾌﾄ原本!C15 -> K.J | C24: =ｼﾌﾄ原本!E15 -> X | D24: =IF(COUNTIF($H$14:$H$30,11),VLOOKUP(11,$H$14:$CU$30,3,FALSE),0) -> 0 | E24: =IF(COUNTIF($H$14:$H$30,11),VLOOKUP(11,$H$14:$CU$30,4,FALSE),0) -> 0 | F24: =IF(COUNTIF($H$14:$H$30,11),VLOOKUP(11,$H$14:$CU$30,92,FALSE),0) -> 0 | G24: =IF(COUNTIF($H$14:$H$30,11),VLOOKUP(11,$H$14:$CW$30,94,FALSE),0) -> 0 | I24: =IF(H24=0,0,LOOKUP(H24,ﾃﾞｰﾀ入力!$C$3:'ﾃﾞｰﾀ入力'!$C$40,ﾃﾞｰﾀ入力!$D$3:'ﾃﾞｰﾀ入力'!$D$40)) -> 0 | L24: =IF(AND(L12>=$J$24,L12<$K$24),"*",0) -> 0 | M24: =IF(AND(M12>=$J$24,M12<$K$24),"*",0) -> 0 | N24: =IF(AND(N12>=$J$24,N12<$K$24),"*",0) -> 0 | O24: =IF(AND(O12>=$J$24,O12<$K$24),"*",0) -> 0 | P24: =IF(AND(P12>=$J$24,P12<$K$24),"*",0) -> 0 | Q24: =IF(AND(Q12>=$J$24,Q12<$K$24),"*",0) -> 0 | R24: =IF(AND(R12>=$J$24,R12<$K$24),"*",0) -> 0 | S24: =IF(AND(S12>=$J$24,S12<$K$24),"*",0) -> 0 | ... CM24: =IF(AND(CM12>=$J$24,CM12<$K$24),"*",0) -> 0 | CN24: =(80-COUNT(L24:CM24))/4 -> 0 | CP24: =IF(CN24=0,0,LOOKUP(CN24,ﾃﾞｰﾀ入力!$AR$13:'ﾃﾞｰﾀ入力'!$AR$34,ﾃﾞｰﾀ入力!$AS$13:'ﾃﾞｰﾀ入力'!$AS$34)) -> 0 | CR24: =IF(CP24>8,CP24-8,0) -> 0 | CS24: =IF(CB24="*",(12-COUNT(CB24:CM24))/4,0) -> 0 | CT24: =IF(CR24>CS24,CS24,CR24) -> 0 | CU24: =CV24*CP24+(CV24*0.25*CR24)+(CV24*0.25*CS24)+(CV24*CT24*0.5) -> 0 | CV24: =IF(H24=0,0,LOOKUP(H24,ﾃﾞｰﾀ入力!$C$3:'ﾃﾞｰﾀ入力'!$C$52,ﾃﾞｰﾀ入力!$E$3:'ﾃﾞｰﾀ入力'!$E$51)) -> 0 | CW24: =IF(H24=0,0,LOOKUP(H24,ﾃﾞｰﾀ入力!$C$3:'ﾃﾞｰﾀ入力'!$C$52,ﾃﾞｰﾀ入力!$F$3:'ﾃﾞｰﾀ入力'!$F$51)) -> 0
A25: =A24+1 -> 12 | B25: =ｼﾌﾄ原本!C16 -> Y.K | C25: =ｼﾌﾄ原本!E16 -> X | D25: =IF(COUNTIF($H$14:$H$30,12),VLOOKUP(12,$H$14:$CU$30,3,FALSE),0) -> 0 | E25: =IF(COUNTIF($H$14:$H$30,12),VLOOKUP(12,$H$14:$CU$30,4,FALSE),0) -> 0 | F25: =IF(COUNTIF($H$14:$H$30,12),VLOOKUP(12,$H$14:$CU$30,92,FALSE),0) -> 0 | G25: =IF(COUNTIF($H$14:$H$30,12),VLOOKUP(12,$H$14:$CW$30,94,FALSE),0) -> 0 | I25: =IF(H25=0,0,LOOKUP(H25,ﾃﾞｰﾀ入力!$C$3:'ﾃﾞｰﾀ入力'!$C$40,ﾃﾞｰﾀ入力!$D$3:'ﾃﾞｰﾀ入力'!$D$40)) -> 0 | L25: =IF(AND(L12>=$J$25,L12<$K$25),"*",0) -> 0 | M25: =IF(AND(M12>=$J$25,M12<$K$25),"*",0) -> 0 | N25: =IF(AND(N12>=$J$25,N12<$K$25),"*",0) -> 0 | O25: =IF(AND(O12>=$J$25,O12<$K$25),"*",0) -> 0 | P25: =IF(AND(P12>=$J$25,P12<$K$25),"*",0) -> 0 | Q25: =IF(AND(Q12>=$J$25,Q12<$K$25),"*",0) -> 0 | R25: =IF(AND(R12>=$J$25,R12<$K$25),"*",0) -> 0 | S25: =IF(AND(S12>=$J$25,S12<$K$25),"*",0) -> 0 | ... CM25: =IF(AND(CM12>=$J$25,CM12<$K$25),"*",0) -> 0 | CN25: =(80-COUNT(L25:CM25))/4 -> 0 | CP25: =IF(CN25=0,0,LOOKUP(CN25,ﾃﾞｰﾀ入力!$AR$13:'ﾃﾞｰﾀ入力'!$AR$34,ﾃﾞｰﾀ入力!$AS$13:'ﾃﾞｰﾀ入力'!$AS$34)) -> 0 | CR25: =IF(CP25>8,CP25-8,0) -> 0 | CS25: =IF(CB25="*",(12-COUNT(CB25:CM25))/4,0) -> 0 | CT25: =IF(CR25>CS25,CS25,CR25) -> 0 | CU25: =CV25*CP25+(CV25*0.25*CR25)+(CV25*0.25*CS25)+(CV25*CT25*0.5) -> 0 | CV25: =IF(H25=0,0,LOOKUP(H25,ﾃﾞｰﾀ入力!$C$3:'ﾃﾞｰﾀ入力'!$C$52,ﾃﾞｰﾀ入力!$E$3:'ﾃﾞｰﾀ入力'!$E$51)) -> 0 | CW25: =IF(H25=0,0,LOOKUP(H25,ﾃﾞｰﾀ入力!$C$3:'ﾃﾞｰﾀ入力'!$C$52,ﾃﾞｰﾀ入力!$F$3:'ﾃﾞｰﾀ入力'!$F$51)) -> 0
A26: =A25+1 -> 13 | B26: =ｼﾌﾄ原本!C17 -> T.R | C26: =ｼﾌﾄ原本!E17 -> 10-20 | D26: =IF(COUNTIF($H$14:$H$30,13),VLOOKUP(13,$H$14:$CU$30,3,FALSE),0) -> 10 | E26: =IF(COUNTIF($H$14:$H$30,13),VLOOKUP(13,$H$14:$CU$30,4,FALSE),0) -> 20 | F26: =IF(COUNTIF($H$14:$H$30,13),VLOOKUP(13,$H$14:$CU$30,92,FALSE),0) -> 11340.5 | G26: =IF(COUNTIF($H$14:$H$30,13),VLOOKUP(13,$H$14:$CW$30,94,FALSE),0) -> 900 | I26: =IF(H26=0,0,LOOKUP(H26,ﾃﾞｰﾀ入力!$C$3:'ﾃﾞｰﾀ入力'!$C$40,ﾃﾞｰﾀ入力!$D$3:'ﾃﾞｰﾀ入力'!$D$40)) -> 0 | L26: =IF(AND(L12>=$J$26,L12<$K$26),"*",0) -> 0 | M26: =IF(AND(M12>=$J$26,M12<$K$26),"*",0) -> 0 | N26: =IF(AND(N12>=$J$26,N12<$K$26),"*",0) -> 0 | O26: =IF(AND(O12>=$J$26,O12<$K$26),"*",0) -> 0 | P26: =IF(AND(P12>=$J$26,P12<$K$26),"*",0) -> 0 | Q26: =IF(AND(Q12>=$J$26,Q12<$K$26),"*",0) -> 0 | R26: =IF(AND(R12>=$J$26,R12<$K$26),"*",0) -> 0 | S26: =IF(AND(S12>=$J$26,S12<$K$26),"*",0) -> 0 | ... CM26: =IF(AND(CM12>=$J$26,CM12<$K$26),"*",0) -> 0 | CN26: =(80-COUNT(L26:CM26))/4 -> 0 | CP26: =IF(CN26=0,0,LOOKUP(CN26,ﾃﾞｰﾀ入力!$AR$13:'ﾃﾞｰﾀ入力'!$AR$34,ﾃﾞｰﾀ入力!$AS$13:'ﾃﾞｰﾀ入力'!$AS$34)) -> 0 | CR26: =IF(CP26>8,CP26-8,0) -> 0 | CS26: =IF(CB26="*",(12-COUNT(CB26:CM26))/4,0) -> 0 | CT26: =IF(CR26>CS26,CS26,CR26) -> 0 | CU26: =CV26*CP26+(CV26*0.25*CR26)+(CV26*0.25*CS26)+(CV26*CT26*0.5) -> 0 | CV26: =IF(H26=0,0,LOOKUP(H26,ﾃﾞｰﾀ入力!$C$3:'ﾃﾞｰﾀ入力'!$C$52,ﾃﾞｰﾀ入力!$E$3:'ﾃﾞｰﾀ入力'!$E$51)) -> 0 | CW26: =IF(H26=0,0,LOOKUP(H26,ﾃﾞｰﾀ入力!$C$3:'ﾃﾞｰﾀ入力'!$C$52,ﾃﾞｰﾀ入力!$F$3:'ﾃﾞｰﾀ入力'!$F$51)) -> 0
A27: =A26+1 -> 14 | B27: =ｼﾌﾄ原本!C18 -> I.N | C27: =ｼﾌﾄ原本!E18 -> X | D27: =IF(COUNTIF($H$14:$H$30,14),VLOOKUP(14,$H$14:$CU$30,3,FALSE),0) -> 0 | E27: =IF(COUNTIF($H$14:$H$30,14),VLOOKUP(14,$H$14:$CU$30,4,FALSE),0) -> 0 | F27: =IF(COUNTIF($H$14:$H$30,14),VLOOKUP(14,$H$14:$CU$30,92,FALSE),0) -> 0 | G27: =IF(COUNTIF($H$14:$H$30,14),VLOOKUP(14,$H$14:$CW$30,94,FALSE),0) -> 0 | I27: =IF(H27=0,0,LOOKUP(H27,ﾃﾞｰﾀ入力!$C$3:'ﾃﾞｰﾀ入力'!$C$40,ﾃﾞｰﾀ入力!$D$3:'ﾃﾞｰﾀ入力'!$D$40)) -> 0 | L27: =IF(AND(L$12>=$J$27,L$12<$K$27),"*",0) -> 0 | M27: =IF(AND(M$12>=$J$27,M$12<$K$27),"*",0) -> 0 | N27: =IF(AND(N$12>=$J$27,N$12<$K$27),"*",0) -> 0 | O27: =IF(AND(O$12>=$J$27,O$12<$K$27),"*",0) -> 0 | P27: =IF(AND(P$12>=$J$27,P$12<$K$27),"*",0) -> 0 | Q27: =IF(AND(Q12>=$J$27,Q12<$K$27),"*",0) -> 0 | R27: =IF(AND(R12>=$J$27,R12<$K$27),"*",0) -> 0 | S27: =IF(AND(S12>=$J$27,S12<$K$27),"*",0) -> 0 | T27: =IF(AND(T12>=$J$27,T12<$K$27),"*",0) -> 0 | U27: =IF(AND(U12>=$J$27,U12<$K$27),"*",0) -> 0 | V27: =IF(AND(V12>=$J$27,V12<$K$27),"*",0) -> 0 | W27: =IF(AND(W12>=$J$27,W12<$K$27),"*",0) -> 0 | X27: =IF(AND(X12>=$J$27,X12<$K$27),"*",0) -> 0 | ... CM27: =IF(AND(CM12>=$J$27,CM12<$K$27),"*",0) -> 0 | CN27: =(80-COUNT(L27:CM27))/4 -> 0 | CP27: =IF(CN27=0,0,LOOKUP(CN27,ﾃﾞｰﾀ入力!$AR$13:'ﾃﾞｰﾀ入力'!$AR$34,ﾃﾞｰﾀ入力!$AS$13:'ﾃﾞｰﾀ入力'!$AS$34)) -> 0 | CR27: =IF(CP27>8,CP27-8,0) -> 0 | CS27: =IF(CB27="*",(12-COUNT(CB27:CM27))/4,0) -> 0 | CT27: =IF(CR27>CS27,CS27,CR27) -> 0 | CU27: =CV27*CP27+(CV27*0.25*CR27)+(CV27*0.25*CS27)+(CV27*CT27*0.5) -> 0 | CV27: =IF(H27=0,0,LOOKUP(H27,ﾃﾞｰﾀ入力!$C$3:'ﾃﾞｰﾀ入力'!$C$52,ﾃﾞｰﾀ入力!$E$3:'ﾃﾞｰﾀ入力'!$E$51)) -> 0 | CW27: =IF(H27=0,0,LOOKUP(H27,ﾃﾞｰﾀ入力!$C$3:'ﾃﾞｰﾀ入力'!$C$52,ﾃﾞｰﾀ入力!$F$3:'ﾃﾞｰﾀ入力'!$F$51)) -> 0
A28: =A27+1 -> 15 | B28: =ｼﾌﾄ原本!C19 -> W.M | C28: =ｼﾌﾄ原本!E19 -> 11-16 | D28: =IF(COUNTIF($H$14:$H$30,15),VLOOKUP(15,$H$14:$CU$30,3,FALSE),0) -> 0 | E28: =IF(COUNTIF($H$14:$H$30,15),VLOOKUP(15,$H$14:$CU$30,4,FALSE),0) -> 0 | F28: =IF(COUNTIF($H$14:$H$30,15),VLOOKUP(15,$H$14:$CU$30,92,FALSE),0) -> 0 | G28: =IF(COUNTIF($H$14:$H$30,15),VLOOKUP(15,$H$14:$CW$30,94,FALSE),0) -> 376 | I28: =IF(H28=0,0,LOOKUP(H28,ﾃﾞｰﾀ入力!$C$3:'ﾃﾞｰﾀ入力'!$C$40,ﾃﾞｰﾀ入力!$D$3:'ﾃﾞｰﾀ入力'!$D$40)) -> 0 | L28: =IF(AND(L$12>=$J$28,L$12<$K$28),"*",0) -> 0 | M28: =IF(AND(M$12>=$J$28,M$12<$K$28),"*",0) -> 0 | N28: =IF(AND(N$12>=$J$28,N$12<$K$28),"*",0) -> 0 | O28: =IF(AND(O$12>=$J$28,O$12<$K$28),"*",0) -> 0 | P28: =IF(AND(P$12>=$J$28,P$12<$K$28),"*",0) -> 0 | Q28: =IF(AND(Q$12>=$J$28,Q$12<$K$28),"*",0) -> 0 | R28: =IF(AND(R$12>=$J$28,R$12<$K$28),"*",0) -> 0 | S28: =IF(AND(S$12>=$J$28,S$12<$K$28),"*",0) -> 0 | ... CM28: =IF(AND(CM$12>=$J$28,CM$12<$K$28),"*",0) -> 0 | CN28: =(80-COUNT(L28:CM28))/4 -> 0 | CP28: =IF(CN28=0,0,LOOKUP(CN28,ﾃﾞｰﾀ入力!$AR$13:'ﾃﾞｰﾀ入力'!$AR$34,ﾃﾞｰﾀ入力!$AS$13:'ﾃﾞｰﾀ入力'!$AS$34)) -> 0 | CR28: =IF(CP28>8,CP28-8,0) -> 0 | CS28: =IF(CB28="*",(12-COUNT(CB28:CM28))/4,0) -> 0 | CT28: =IF(CR28>CS28,CS28,CR28) -> 0 | CU28: =CV28*CP28+(CV28*0.25*CR28)+(CV28*0.25*CS28)+(CV28*CT28*0.5) -> 0 | CV28: =IF(H28=0,0,LOOKUP(H28,ﾃﾞｰﾀ入力!$C$3:'ﾃﾞｰﾀ入力'!$C$52,ﾃﾞｰﾀ入力!$E$3:'ﾃﾞｰﾀ入力'!$E$51)) -> 0 | CW28: =IF(H28=0,0,LOOKUP(H28,ﾃﾞｰﾀ入力!$C$3:'ﾃﾞｰﾀ入力'!$C$52,ﾃﾞｰﾀ入力!$F$3:'ﾃﾞｰﾀ入力'!$F$51)) -> 0
A29: =A28+1 -> 16 | B29: =ｼﾌﾄ原本!C20 -> Y.Y | C29: =ｼﾌﾄ原本!E20 -> X | D29: =IF(COUNTIF($H$14:$H$30,16),VLOOKUP(16,$H$14:$CU$30,3,FALSE),0) -> 0 | E29: =IF(COUNTIF($H$14:$H$30,16),VLOOKUP(16,$H$14:$CU$30,4,FALSE),0) -> 0 | F29: =IF(COUNTIF($H$14:$H$30,16),VLOOKUP(16,$H$14:$CU$30,92,FALSE),0) -> 0 | G29: =IF(COUNTIF($H$14:$H$30,16),VLOOKUP(16,$H$14:$CW$30,94,FALSE),0) -> 0 | I29: =IF(H29=0,0,LOOKUP(H29,ﾃﾞｰﾀ入力!$C$3:'ﾃﾞｰﾀ入力'!$C$40,ﾃﾞｰﾀ入力!$D$3:'ﾃﾞｰﾀ入力'!$D$40)) -> 0 | L29: =IF(AND(L$12>=$J$29,L$12<$K$29),"*",0) -> 0 | M29: =IF(AND(M$12>=$J$29,M$12<$K$29),"*",0) -> 0 | N29: =IF(AND(N$12>=$J$29,N$12<$K$29),"*",0) -> 0 | O29: =IF(AND(O$12>=$J$29,O$12<$K$29),"*",0) -> 0 | P29: =IF(AND(P$12>=$J$29,P$12<$K$29),"*",0) -> 0 | Q29: =IF(AND(Q$12>=$J$29,Q$12<$K$29),"*",0) -> 0 | R29: =IF(AND(R$12>=$J$29,R$12<$K$29),"*",0) -> 0 | S29: =IF(AND(S$12>=$J$29,S$12<$K$29),"*",0) -> 0 | ... CM29: =IF(AND(CM$12>=$J$29,CM$12<$K$29),"*",0) -> 0 | CN29: =(80-COUNT(L29:CM29))/4 -> 0 | CP29: =IF(CN29=0,0,LOOKUP(CN29,ﾃﾞｰﾀ入力!$AR$13:'ﾃﾞｰﾀ入力'!$AR$34,ﾃﾞｰﾀ入力!$AS$13:'ﾃﾞｰﾀ入力'!$AS$34)) -> 0 | CR29: =IF(CP29>8,CP29-8,0) -> 0 | CS29: =IF(CB29="*",(12-COUNT(CB29:CM29))/4,0) -> 0 | CT29: =IF(CR29>CS29,CS29,CR29) -> 0 | CU29: =CV29*CP29+(CV29*0.25*CR29)+(CV29*0.25*CS29)+(CV29*CT29*0.5) -> 0 | CV29: =IF(H29=0,0,LOOKUP(H29,ﾃﾞｰﾀ入力!$C$3:'ﾃﾞｰﾀ入力'!$C$52,ﾃﾞｰﾀ入力!$E$3:'ﾃﾞｰﾀ入力'!$E$51)) -> 0 | CW29: =IF(H29=0,0,LOOKUP(H29,ﾃﾞｰﾀ入力!$C$3:'ﾃﾞｰﾀ入力'!$C$52,ﾃﾞｰﾀ入力!$F$3:'ﾃﾞｰﾀ入力'!$F$51)) -> 0
A30: =A29+1 -> 17 | B30: =ｼﾌﾄ原本!C21 -> S.U | C30: =ｼﾌﾄ原本!E21 -> X | D30: =IF(COUNTIF($H$14:$H$30,17),VLOOKUP(17,$H$14:$CU$30,3,FALSE),0) -> 0 | E30: =IF(COUNTIF($H$14:$H$30,17),VLOOKUP(17,$H$14:$CU$30,4,FALSE),0) -> 0 | F30: =IF(COUNTIF($H$14:$H$30,17),VLOOKUP(17,$H$14:$CU$30,92,FALSE),0) -> 0 | G30: =IF(COUNTIF($H$14:$H$30,17),VLOOKUP(17,$H$14:$CW$30,94,FALSE),0) -> 0 | I30: =IF(H30=0,0,LOOKUP(H30,ﾃﾞｰﾀ入力!$C$3:'ﾃﾞｰﾀ入力'!$C$40,ﾃﾞｰﾀ入力!$D$3:'ﾃﾞｰﾀ入力'!$D$40)) -> 0 | L30: =IF(AND(L12>=$J$30,L12<$K$30),"*",0) -> 0 | M30: =IF(AND(M12>=$J$30,M12<$K$30),"*",0) -> 0 | N30: =IF(AND(N12>=$J$30,N12<$K$30),"*",0) -> 0 | O30: =IF(AND(O12>=$J$30,O12<$K$30),"*",0) -> 0 | P30: =IF(AND(P12>=$J$30,P12<$K$30),"*",0) -> 0 | Q30: =IF(AND(Q12>=$J$30,Q12<$K$30),"*",0) -> 0 | R30: =IF(AND(R12>=$J$30,R12<$K$30),"*",0) -> 0 | S30: =IF(AND(S12>=$J$30,S12<$K$30),"*",0) -> 0 | ... CM30: =IF(AND(CM12>=$J$30,CM12<$K$30),"*",0) -> 0 | CN30: =(80-COUNT(L30:CM30))/4 -> 0 | CP30: =IF(CN30=0,0,LOOKUP(CN30,ﾃﾞｰﾀ入力!$AR$13:'ﾃﾞｰﾀ入力'!$AR$34,ﾃﾞｰﾀ入力!$AS$13:'ﾃﾞｰﾀ入力'!$AS$34)) -> 0 | CR30: =IF(CP30>8,CP30-8,0) -> 0 | CS30: =IF(CB30="*",(12-COUNT(CB30:CM30))/4,0) -> 0 | CT30: =IF(CR30>CS30,CS30,CR30) -> 0 | CU30: =CV30*CP30+(CV30*0.25*CR30)+(CV30*0.25*CS30)+(CV30*CT30*0.5) -> 0 | CV30: =IF(H30=0,0,LOOKUP(H30,ﾃﾞｰﾀ入力!$C$3:'ﾃﾞｰﾀ入力'!$C$52,ﾃﾞｰﾀ入力!$E$3:'ﾃﾞｰﾀ入力'!$E$51)) -> 0 | CW30: =IF(H30=0,0,LOOKUP(H30,ﾃﾞｰﾀ入力!$C$3:'ﾃﾞｰﾀ入力'!$C$52,ﾃﾞｰﾀ入力!$F$3:'ﾃﾞｰﾀ入力'!$F$51)) -> 0
A31: =A30+1 -> 18 | B31: =ｼﾌﾄ原本!C22 -> A.A | C31: =ｼﾌﾄ原本!E22 -> X | D31: =IF(COUNTIF($H$14:$H$30,18),VLOOKUP(18,$H$14:$CU$30,3,FALSE),0) -> 0 | E31: =IF(COUNTIF($H$14:$H$30,18),VLOOKUP(18,$H$14:$CU$30,4,FALSE),0) -> 0 | F31: =IF(COUNTIF($H$14:$H$30,18),VLOOKUP(18,$H$14:$CU$30,92,FALSE),0) -> 0 | G31: =IF(COUNTIF($H$14:$H$30,18),VLOOKUP(18,$H$14:$CW$30,94,FALSE),0) -> 0 | I31: =COUNT(H14:H30) -> 8 | J31: 時間帯別計画時間 | L31: =(68-COUNT(L$14:O$30))/4 -> 0 | P31: =(68-COUNT(P$14:S$30))/4 -> 0.25 | T31: =(68-COUNT(T$14:W$30))/4 -> 2 | X31: =(68-COUNT(X$14:AA$30))/4 -> 2 | AB31: =(68-COUNT(AB$14:AE$30))/4 -> 2 | AF31: =(68-COUNT(AF$14:AI$30))/4 -> 3 | AJ31: =(68-COUNT(AJ$14:AM$30))/4 -> 4 | AN31: =(68-COUNT(AN$14:AQ$30))/4 -> 6 | AR31: =(68-COUNT(AR$14:AU$30))/4 -> 6 | AV31: =(68-COUNT(AV$14:AY$30))/4 -> 6 | AZ31: =(68-COUNT(AZ$14:BC$30))/4 -> 6 | BD31: =(68-COUNT(BD$14:BG$30))/4 -> 4 | BH31: =(68-COUNT(BH$14:BK$30))/4 -> 3 | BL31: =(68-COUNT(BL$14:BO$30))/4 -> 4 | BP31: =(68-COUNT(BP$14:BS$30))/4 -> 4 | BT31: =(68-COUNT(BT$14:BW$30))/4 -> 3 | BX31: =(68-COUNT(BX$14:CA$30))/4 -> 3 | CB31: =(68-COUNT(CB$14:CE$30))/4 -> 2.25 | CF31: =(68-COUNT(CF$14:CI$30))/4 -> 0 | CJ31: =(68-COUNT(CJ$14:CM$30))/4 -> 0 | CN31: =SUM(CN14:CN30) -> 60.5 | CP31: =SUM(CP14:CP30) -> 54.5 | CR31: =SUM(CR14:CR30) -> 5 | CS31: =SUM(CS14:CS30) -> 2.25 | CT31: =SUM(CT14:CT30) -> 1.5 | CU31: =SUM(CU14:CU30) -> 81777.375 | CV31: =SUM(CV14:CV30) -> 10958 | CW31: =SUM(CW14:CW30) -> 5402
A32: =A31+1 -> 19 | B32: =ｼﾌﾄ原本!C23 -> E.U | C32: =ｼﾌﾄ原本!E23 -> X | D32: =IF(COUNTIF($H$14:$H$30,19),VLOOKUP(19,$H$14:$CU$30,3,FALSE),0) -> 0 | E32: =IF(COUNTIF($H$14:$H$30,19),VLOOKUP(19,$H$14:$CU$30,4,FALSE),0) -> 0 | F32: =IF(COUNTIF($H$14:$H$30,19),VLOOKUP(19,$H$14:$CU$30,92,FALSE),0) -> 0 | G32: =IF(COUNTIF($H$14:$H$30,19),VLOOKUP(19,$H$14:$CW$30,94,FALSE),0) -> 0 | J32: 時間別人時売上高 | L32: =IF(ISERROR(L3*1000/(L31-L8-L10)),"",L3*1000/(L31-L8-L10)) | P32: =IF(ISERROR(P3*1000/(P31-P8-P10)),"",P3*1000/(P31-P8-P10)) -> 0 | T32: =IF(ISERROR(T3*1000/(T31-T8-T10)),"",T3*1000/(T31-T8-T10)) -> 0 | X32: =IF(ISERROR(X3*1000/(X31-X8-X10)),"",X3*1000/(X31-X8-X10)) -> 3500 | AB32: =IF(ISERROR(AB3*1000/(AB31-AB8-AB10)),"",AB3*1000/(AB31-AB8-AB10)) -> 6500 | AF32: =IF(ISERROR(AF3*1000/(AF31-AF8-AF10)),"",AF3*1000/(AF31-AF8-AF10)) -> 4333.3333 | AJ32: =IF(ISERROR(AJ3*1000/(AJ31-AJ8-AJ10)),"",AJ3*1000/(AJ31-AJ8-AJ10)) -> 4500 | AN32: =IF(ISERROR(AN3*1000/(AN31-AN8-AN10)),"",AN3*1000/(AN31-AN8-AN10)) -> 4666.6667 | AR32: =IF(ISERROR(AR3*1000/(AR31-AR8-AR10)),"",AR3*1000/(AR31-AR8-AR10)) -> 5166.6667 | AV32: =IF(ISERROR(AV3*1000/(AV31-AV8-AV10)),"",AV3*1000/(AV31-AV8-AV10)) -> 5000 | AZ32: =IF(ISERROR(AZ3*1000/(AZ31-AZ8-AZ10)),"",AZ3*1000/(AZ31-AZ8-AZ10)) -> 5333.3333 | BD32: =IF(ISERROR(BD3*1000/(BD31-BD8-BD10)),"",BD3*1000/(BD31-BD8-BD10)) -> 7500 | BH32: =IF(ISERROR(BH3*1000/(BH31-BH8-BH10)),"",BH3*1000/(BH31-BH8-BH10)) -> 7000 | BL32: =IF(ISERROR(BL3*1000/(BL31-BL8-BL10)),"",BL3*1000/(BL31-BL8-BL10)) -> 3750 | BP32: =IF(ISERROR(BP3*1000/(BP31-BP8-BP10)),"",BP3*1000/(BP31-BP8-BP10)) -> 4000 | BT32: =IF(ISERROR(BT3*1000/(BT31-BT8-BT10)),"",BT3*1000/(BT31-BT8-BT10)) -> 4000 | BX32: =IF(ISERROR(BX3*1000/(BX31-BX8-BX10)),"",BX3*1000/(BX31-BX8-BX10)) -> 1333.3333 | CB32: =IF(ISERROR(CB3*1000/(CB31-CB8-CB10)),"",CB3*1000/(CB31-CB8-CB10)) -> 0 | CF32: =IF(ISERROR(CF3*1000/(CF31-CF8-CF10)),"",CF3*1000/(CF31-CF8-CF10)) | CJ32: =IF(ISERROR(CJ3*1000/(CJ31-CJ8-CJ10)),"",CJ3*1000/(CJ31-CJ8-CJ10))
A33: =A32+1 -> 20 | B33: =ｼﾌﾄ原本!C24 -> S.S | C33: =ｼﾌﾄ原本!E24 -> X | D33: =IF(COUNTIF($H$14:$H$30,20),VLOOKUP(20,$H$14:$CU$30,3,FALSE),0) -> 0 | E33: =IF(COUNTIF($H$14:$H$30,20),VLOOKUP(20,$H$14:$CU$30,4,FALSE),0) -> 0 | F33: =IF(COUNTIF($H$14:$H$30,20),VLOOKUP(20,$H$14:$CU$30,92,FALSE),0) -> 0 | G33: =IF(COUNTIF($H$14:$H$30,20),VLOOKUP(20,$H$14:$CW$30,94,FALSE),0) -> 0 | AB33: 1 | AF33: 週目
A34: =A33+1 -> 21 | B34: =ｼﾌﾄ原本!C25 -> S.K | C34: =ｼﾌﾄ原本!E25 -> F | D34: =IF(COUNTIF($H$14:$H$30,21),VLOOKUP(21,$H$14:$CU$30,3,FALSE),0) -> 12 | E34: =IF(COUNTIF($H$14:$H$30,21),VLOOKUP(21,$H$14:$CU$30,4,FALSE),0) -> 17 | F34: =IF(COUNTIF($H$14:$H$30,21),VLOOKUP(21,$H$14:$CU$30,92,FALSE),0) -> 6130 | G34: =IF(COUNTIF($H$14:$H$30,21),VLOOKUP(21,$H$14:$CW$30,94,FALSE),0) -> 682 | J34: シフト | L34: 実行計画 | Z34: Ｓales Action | BH34: Daily Cleanliness | BV34: PMC
A35: =A34+1 -> 22 | B35: =ｼﾌﾄ原本!C26 -> 0 | C35: =ｼﾌﾄ原本!E26 -> 0 | D35: =IF(COUNTIF($H$14:$H$30,22),VLOOKUP(22,$H$14:$CU$30,3,FALSE),0) -> 0 | E35: =IF(COUNTIF($H$14:$H$30,22),VLOOKUP(22,$H$14:$CU$30,4,FALSE),0) -> 0 | F35: =IF(COUNTIF($H$14:$H$30,22),VLOOKUP(22,$H$14:$CU$30,92,FALSE),0) -> 0 | G35: =IF(COUNTIF($H$14:$H$30,22),VLOOKUP(22,$H$14:$CW$30,94,FALSE),0) -> 0 | I35: 売上 | J35: =CN3*1000 -> 270000 | Z35: =CHOOSE($AB$33,'セールスアクション '!B5,'セールスアクション '!B13,'セールスアクション '!B21,'セールスアクション '!B29,'セールスアクション '!B37) -> 0 | AZ35: =CHOOSE($AB$33,'セールスアクション '!I5,'セールスアクション '!I13,'セールスアクション '!I21,'セールスアクション '!I29,'セールスアクション '!I37) -> 0 | BH35: =CHOOSE($CA$1,PMC.D!D6,PMC.D!D15,PMC.D!D24,PMC.D!D33,PMC.D!D42,PMC.D!D51) -> 0 | BV35: =CHOOSE($CA$1,PMC.D!J6,PMC.D!J15,PMC.D!J24,PMC.D!J33,PMC.D!J42,PMC.D!J51) -> 0
A36: =A35+1 -> 23 | B36: =ｼﾌﾄ原本!C27 -> 0 | C36: =ｼﾌﾄ原本!E27 -> 0 | D36: =IF(COUNTIF($H$14:$H$30,23),VLOOKUP(23,$H$14:$CU$30,3,FALSE),0) -> 0 | E36: =IF(COUNTIF($H$14:$H$30,23),VLOOKUP(23,$H$14:$CU$30,4,FALSE),0) -> 0 | F36: =IF(COUNTIF($H$14:$H$30,23),VLOOKUP(23,$H$14:$CU$30,92,FALSE),0) -> 0 | G36: =IF(COUNTIF($H$14:$H$30,23),VLOOKUP(23,$H$14:$CW$30,94,FALSE),0) -> 0 | I36: 来客数 | J36: =CHOOSE($CA$1,ﾃﾞｰﾀ入力!W4,ﾃﾞｰﾀ入力!W5,ﾃﾞｰﾀ入力!W6,ﾃﾞｰﾀ入力!W7,ﾃﾞｰﾀ入力!W8,ﾃﾞｰﾀ入力!W9) -> 361 | Z36: =CHOOSE($AB$33,'セールスアクション '!B6,'セールスアクション '!B14,'セールスアクション '!B22,'セールスアクション '!B30,'セールスアクション '!B38) -> 0 | AZ36: =CHOOSE($AB$33,'セールスアクション '!I6,'セールスアクション '!I14,'セールスアクション '!I22,'セールスアクション '!I30,'セールスアクション '!I38) -> 0 | BH36: =CHOOSE($CA$1,PMC.D!D7,PMC.D!D16,PMC.D!D25,PMC.D!D34,PMC.D!D43,PMC.D!D52) -> 0 | BV36: =CHOOSE($CA$1,PMC.D!J7,PMC.D!J16,PMC.D!J25,PMC.D!J34,PMC.D!J43,PMC.D!J52) -> 0
A37: =A36+1 -> 24 | B37: =ｼﾌﾄ原本!C28 -> 0 | C37: =ｼﾌﾄ原本!E28 -> 0 | D37: =IF(COUNTIF($H$14:$H$30,24),VLOOKUP(24,$H$14:$CU$30,3,FALSE),0) -> 0 | E37: =IF(COUNTIF($H$14:$H$30,24),VLOOKUP(24,$H$14:$CU$30,4,FALSE),0) -> 0 | F37: =IF(COUNTIF($H$14:$H$30,24),VLOOKUP(24,$H$14:$CU$30,92,FALSE),0) -> 0 | G37: =IF(COUNTIF($H$14:$H$30,24),VLOOKUP(24,$H$14:$CW$30,94,FALSE),0) -> 0 | I37: 人時売上高 | J37: =J35/(K39+J39) -> 4954.1284 | L37: =J35/L40 -> 6923.0769 | Z37: =CHOOSE($AB$33,'セールスアクション '!B7,'セールスアクション '!B15,'セールスアクション '!B23,'セールスアクション '!B31,'セールスアクション '!B39) -> 0 | AZ37: =CHOOSE($AB$33,'セールスアクション '!I7,'セールスアクション '!I15,'セールスアクション '!I23,'セールスアクション '!I31,'セールスアクション '!I39) -> 0 | BH37: =CHOOSE($CA$1,PMC.D!D8,PMC.D!D17,PMC.D!D26,PMC.D!D35,PMC.D!D44,PMC.D!D53) -> 0 | BV37: =CHOOSE($CA$1,PMC.D!J8,PMC.D!J17,PMC.D!J26,PMC.D!J35,PMC.D!J44,PMC.D!J53) -> 0
A38: =A37+1 -> 25 | B38: =ｼﾌﾄ原本!C29 -> 0 | C38: =ｼﾌﾄ原本!E29 -> 0 | D38: =IF(COUNTIF($H$14:$H$30,25),VLOOKUP(25,$H$14:$CU$30,3,FALSE),0) -> 0 | E38: =IF(COUNTIF($H$14:$H$30,25),VLOOKUP(25,$H$14:$CU$30,4,FALSE),0) -> 0 | F38: =IF(COUNTIF($H$14:$H$30,25),VLOOKUP(25,$H$14:$CU$30,92,FALSE),0) -> 0 | G38: =IF(COUNTIF($H$14:$H$30,25),VLOOKUP(25,$H$14:$CW$30,94,FALSE),0) -> 0 | I38: 人時接客数 | J38: =J36/(J39+K39) -> 6.6238532 | L38: =J36/L40 -> 9.2564103 | Z38: =CHOOSE($AB$33,'セールスアクション '!B8,'セールスアクション '!B16,'セールスアクション '!B24,'セールスアクション '!B32,'セールスアクション '!B40) -> 0 | AZ38: =CHOOSE($AB$33,'セールスアクション '!I8,'セールスアクション '!I16,'セールスアクション '!I24,'セールスアクション '!I32,'セールスアクション '!I40) -> 0 | BH38: =CHOOSE($CA$1,PMC.D!D9,PMC.D!D18,PMC.D!D27,PMC.D!D36,PMC.D!D45,PMC.D!D54) -> 0 | BV38: =CHOOSE($CA$1,PMC.D!J9,PMC.D!J18,PMC.D!J27,PMC.D!J36,PMC.D!J45,PMC.D!J54) -> 0
A39: =A38+1 -> 26 | B39: =ｼﾌﾄ原本!C30 -> 0 | C39: =ｼﾌﾄ原本!E30 -> 0 | D39: =IF(COUNTIF($H$14:$H$30,26),VLOOKUP(26,$H$14:$CU$30,3,FALSE),0) -> 0 | E39: =IF(COUNTIF($H$14:$H$30,26),VLOOKUP(26,$H$14:$CU$30,4,FALSE),0) -> 0 | F39: =IF(COUNTIF($H$14:$H$30,26),VLOOKUP(26,$H$14:$CU$30,92,FALSE),0) -> 0 | G39: =IF(COUNTIF($H$14:$H$30,26),VLOOKUP(26,$H$14:$CW$30,94,FALSE),0) -> 0 | I39: 労働時間 | J39: =SUMIF(CV14:CV30,">1500",CP14:CQ30) -> 9.5 | K39: =SUMIF(CV14:CV30,"<2000",CP14:CP30) -> 45 | L39: =SUMIF(CV14:CV30,">1500",CP14:CQ30) -> 9.5 | R39: =L40-L39 -> 29.5 | Z39: =CHOOSE($AB$33,'セールスアクション '!B9,'セールスアクション '!B17,'セールスアクション '!B25,'セールスアクション '!B33,'セールスアクション '!B41) -> 0 | AZ39: =CHOOSE($AB$33,'セールスアクション '!I9,'セールスアクション '!I17,'セールスアクション '!I25,'セールスアクション '!I33,'セールスアクション '!I41) -> 0 | BH39: =CHOOSE($CA$1,PMC.D!D10,PMC.D!D19,PMC.D!D28,PMC.D!D37,PMC.D!D46,PMC.D!D55) -> 0 | BV39: =CHOOSE($CA$1,PMC.D!J10,PMC.D!J19,PMC.D!J28,PMC.D!J37,PMC.D!J46,PMC.D!J55) -> 0
A40: =A39+1 -> 27 | B40: =ｼﾌﾄ原本!C31 -> 0 | C40: =ｼﾌﾄ原本!E31 -> 0 | D40: =IF(COUNTIF($H$14:$H$30,27),VLOOKUP(27,$H$14:$CU$30,3,FALSE),0) -> 0 | E40: =IF(COUNTIF($H$14:$H$30,27),VLOOKUP(27,$H$14:$CU$30,4,FALSE),0) -> 0 | F40: =IF(COUNTIF($H$14:$H$30,27),VLOOKUP(27,$H$14:$CU$30,92,FALSE),0) -> 0 | G40: =IF(COUNTIF($H$14:$H$30,27),VLOOKUP(27,$H$14:$CW$30,94,FALSE),0) -> 0 | I40: 総労働時間 | J40: =J39+K39 -> 54.5 | L40: =CP11 -> 39 | Z40: 銀行 午前中MUST
...

Sheet 2
K1: =ﾃﾞｰﾀ入力!B4 -> 新宿三丁目 | V1: 店 | AC1: =ﾃﾞｰﾀ入力!B5 -> 4 | AJ1: 月 | AN1: 2 | AR1: 日 | AZ1: =DATE(ﾃﾞｰﾀ入力!B3,ﾃﾞｰﾀ入力!B5,AN1) -> 46114 | BD1: 曜日 | BT1: パターン | CA1: 1
L2: 0.20833333 | P2: 0.25 | T2: 7:00 | X2: 8:00 | AB2: 9:00 | AF2: 10:00 | AJ2: 11:00 | AN2: 12:00 | AR2: 13:00 | AV2: 14:00 | AZ2: 15:00 | BD2: 16:00 | BH2: 17:00 | BL2: 18:00 | BP2: 19:00 | BT2: 20:00 | BX2: 21:00 | CB2: 22:00 | CF2: 23:00 | CJ2: 24:00
I3: 実行計画売上（千円） | K3: PLAN | L3: =CHOOSE(CA1,ﾃﾞｰﾀ入力!X4,ﾃﾞｰﾀ入力!X5,ﾃﾞｰﾀ入力!X6,ﾃﾞｰﾀ入力!X7,ﾃﾞｰﾀ入力!X8,ﾃﾞｰﾀ入力!X9) -> 0 | P3: =CHOOSE($CA$1,ﾃﾞｰﾀ入力!Y$4,ﾃﾞｰﾀ入力!Y$5,ﾃﾞｰﾀ入力!Y$6,ﾃﾞｰﾀ入力!Y$7,ﾃﾞｰﾀ入力!Y$8,ﾃﾞｰﾀ入力!Y$9) -> 0 | T3: =CHOOSE($CA$1,ﾃﾞｰﾀ入力!Z$4,ﾃﾞｰﾀ入力!Z$5,ﾃﾞｰﾀ入力!Z$6,ﾃﾞｰﾀ入力!Z$7,ﾃﾞｰﾀ入力!Z$8,ﾃﾞｰﾀ入力!Z$9) -> 0 | X3: =CHOOSE($CA$1,ﾃﾞｰﾀ入力!AA$4,ﾃﾞｰﾀ入力!AA$5,ﾃﾞｰﾀ入力!AA$6,ﾃﾞｰﾀ入力!AA$7,ﾃﾞｰﾀ入力!AA$8,ﾃﾞｰﾀ入力!AA$9) -> 7 | AB3: =CHOOSE($CA$1,ﾃﾞｰﾀ入力!AB$4,ﾃﾞｰﾀ入力!AB$5,ﾃﾞｰﾀ入力!AB$6,ﾃﾞｰﾀ入力!AB$7,ﾃﾞｰﾀ入力!AB$8,ﾃﾞｰﾀ入力!AB$9) -> 13 | AF3: =CHOOSE($CA$1,ﾃﾞｰﾀ入力!AC$4,ﾃﾞｰﾀ入力!AC$5,ﾃﾞｰﾀ入力!AC$6,ﾃﾞｰﾀ入力!AC$7,ﾃﾞｰﾀ入力!AC$8,ﾃﾞｰﾀ入力!AC$9) -> 13 | AJ3: =CHOOSE($CA$1,ﾃﾞｰﾀ入力!AD$4,ﾃﾞｰﾀ入力!AD$5,ﾃﾞｰﾀ入力!AD$6,ﾃﾞｰﾀ入力!AD$7,ﾃﾞｰﾀ入力!AD$8,ﾃﾞｰﾀ入力!AD$9) -> 18 | AN3: =CHOOSE($CA$1,ﾃﾞｰﾀ入力!AE$4,ﾃﾞｰﾀ入力!AE$5,ﾃﾞｰﾀ入力!AE$6,ﾃﾞｰﾀ入力!AE$7,ﾃﾞｰﾀ入力!AE$8,ﾃﾞｰﾀ入力!AE$9) -> 28 | AR3: =CHOOSE($CA$1,ﾃﾞｰﾀ入力!AF$4,ﾃﾞｰﾀ入力!AF$5,ﾃﾞｰﾀ入力!AF$6,ﾃﾞｰﾀ入力!AF$7,ﾃﾞｰﾀ入力!AF$8,ﾃﾞｰﾀ入力!AF$9) -> 31 | AV3: =CHOOSE($CA$1,ﾃﾞｰﾀ入力!AG$4,ﾃﾞｰﾀ入力!AG$5,ﾃﾞｰﾀ入力!AG$6,ﾃﾞｰﾀ入力!AG$7,ﾃﾞｰﾀ入力!AG$8,ﾃﾞｰﾀ入力!AG$9) -> 30 | AZ3: =CHOOSE($CA$1,ﾃﾞｰﾀ入力!AH$4,ﾃﾞｰﾀ入力!AH$5,ﾃﾞｰﾀ入力!AH$6,ﾃﾞｰﾀ入力!AH$7,ﾃﾞｰﾀ入力!AH$8,ﾃﾞｰﾀ入力!AH$9) -> 32 | BD3: =CHOOSE($CA$1,ﾃﾞｰﾀ入力!AI$4,ﾃﾞｰﾀ入力!AI$5,ﾃﾞｰﾀ入力!AI$6,ﾃﾞｰﾀ入力!AI$7,ﾃﾞｰﾀ入力!AI$8,ﾃﾞｰﾀ入力!AI$9) -> 30 | BH3: =CHOOSE($CA$1,ﾃﾞｰﾀ入力!AJ$4,ﾃﾞｰﾀ入力!AJ$5,ﾃﾞｰﾀ入力!AJ$6,ﾃﾞｰﾀ入力!AJ$7,ﾃﾞｰﾀ入力!AJ$8,ﾃﾞｰﾀ入力!AJ$9) -> 21 | BL3: =CHOOSE($CA$1,ﾃﾞｰﾀ入力!AK$4,ﾃﾞｰﾀ入力!AK$5,ﾃﾞｰﾀ入力!AK$6,ﾃﾞｰﾀ入力!AK$7,ﾃﾞｰﾀ入力!AK$8,ﾃﾞｰﾀ入力!AK$9) -> 15 | BP3: =CHOOSE($CA$1,ﾃﾞｰﾀ入力!AL$4,ﾃﾞｰﾀ入力!AL$5,ﾃﾞｰﾀ入力!AL$6,ﾃﾞｰﾀ入力!AL$7,ﾃﾞｰﾀ入力!AL$8,ﾃﾞｰﾀ入力!AL$9) -> 16 | BT3: =CHOOSE($CA$1,ﾃﾞｰﾀ入力!AM$4,ﾃﾞｰﾀ入力!AM$5,ﾃﾞｰﾀ入力!AM$6,ﾃﾞｰﾀ入力!AM$7,ﾃﾞｰﾀ入力!AM$8,ﾃﾞｰﾀ入力!AM$9) -> 12 | BX3: =CHOOSE($CA$1,ﾃﾞｰﾀ入力!AN4,ﾃﾞｰﾀ入力!AN$5,ﾃﾞｰﾀ入力!AN$6,ﾃﾞｰﾀ入力!AN$7,ﾃﾞｰﾀ入力!AN$8,ﾃﾞｰﾀ入力!AN$9) -> 4 | CB3: =CHOOSE($CA$1,ﾃﾞｰﾀ入力!AO$4,ﾃﾞｰﾀ入力!AO$5,ﾃﾞｰﾀ入力!AO$6,ﾃﾞｰﾀ入力!AO$7,ﾃﾞｰﾀ入力!AO$8,ﾃﾞｰﾀ入力!AO$9) -> 0 | CF3: =CHOOSE($CA$1,ﾃﾞｰﾀ入力!AP$4,ﾃﾞｰﾀ入力!AP$5,ﾃﾞｰﾀ入力!AP$6,ﾃﾞｰﾀ入力!AP$7,ﾃﾞｰﾀ入力!AP$8,ﾃﾞｰﾀ入力!AP$9) -> 0 | CJ3: =CHOOSE($CA$1,ﾃﾞｰﾀ入力!AQ$4,ﾃﾞｰﾀ入力!AQ$5,ﾃﾞｰﾀ入力!AQ$6,ﾃﾞｰﾀ入力!AQ$7,ﾃﾞｰﾀ入力!AQ$8,ﾃﾞｰﾀ入力!AQ$9) -> 0 | CN3: =CHOOSE(CA1,ﾃﾞｰﾀ入力!V4,ﾃﾞｰﾀ入力!V5,ﾃﾞｰﾀ入力!V6,ﾃﾞｰﾀ入力!V7,ﾃﾞｰﾀ入力!V8,ﾃﾞｰﾀ入力!V9) -> 270
K4: 累計 | L4: =L3 -> 0 | P4: =L4+P3 -> 0 | T4: =P4+T3 -> 0 | X4: =T4+X3 -> 7 | AB4: =X4+AB3 -> 20 | AF4: =AB4+AF3 -> 33 | AJ4: =AF4+AJ3 -> 51 | AN4: =AJ4+AN3 -> 79 | AR4: =AN4+AR3 -> 110 | AV4: =AR4+AV3 -> 140 | AZ4: =AV4+AZ3 -> 172 | BD4: =AZ4+BD3 -> 202 | BH4: =BD4+BH3 -> 223 | BL4: =BH4+BL3 -> 238 | BP4: =BL4+BP3 -> 254 | BT4: =BP4+BT3 -> 266 | BX4: =BT4+BX3 -> 270 | CB4: =BX4+CB3 -> 270 | CF4: =CB4+CF3 -> 270 | CJ4: =CF4+CJ3 -> 270 | CN4: =SUM(P4:CM4) -> 2875
I5: 売上ACTUAL（千円） | K5: ACTUAL | CN5: =SUM(P5:CM5) -> 0
K6: 累計 | CN6: =SUM(P6:CM6) -> 0
I7: 必要人員数 | K7: PLAN | L7: =IF(L3=0,0,LOOKUP(L3,ﾃﾞｰﾀ入力!$AU$12:$AU$32,ﾃﾞｰﾀ入力!$AV$12:$AV$32)) -> 0 | P7: =IF(P3=0,0,LOOKUP(P3,ﾃﾞｰﾀ入力!$AU$12:$AU$32,ﾃﾞｰﾀ入力!$AV$12:$AV$32)) -> 0 | T7: =IF(T3=0,0,LOOKUP(T3,ﾃﾞｰﾀ入力!$AU$12:$AU$32,ﾃﾞｰﾀ入力!$AV$12:$AV$32)) -> 0 | X7: =IF(X3=0,0,LOOKUP(X3,ﾃﾞｰﾀ入力!$AU$12:$AU$32,ﾃﾞｰﾀ入力!$AV$12:$AV$32)) -> 2 | AB7: =IF(AB3=0,0,LOOKUP(AB3,ﾃﾞｰﾀ入力!$AU$12:$AU$32,ﾃﾞｰﾀ入力!$AV$12:$AV$32)) -> 2 | AF7: =IF(AF3=0,0,LOOKUP(AF3,ﾃﾞｰﾀ入力!$AU$12:$AU$32,ﾃﾞｰﾀ入力!$AV$12:$AV$32)) -> 2 | AJ7: =IF(AJ3=0,0,LOOKUP(AJ3,ﾃﾞｰﾀ入力!$AU$12:$AU$32,ﾃﾞｰﾀ入力!$AV$12:$AV$32)) -> 2 | AN7: =IF(AN3=0,0,LOOKUP(AN3,ﾃﾞｰﾀ入力!$AU$12:$AU$32,ﾃﾞｰﾀ入力!$AV$12:$AV$32)) -> 4 | AR7: =IF(AR3=0,0,LOOKUP(AR3,ﾃﾞｰﾀ入力!$AU$12:$AU$32,ﾃﾞｰﾀ入力!$AV$12:$AV$32)) -> 4 | AV7: =IF(AV3=0,0,LOOKUP(AV3,ﾃﾞｰﾀ入力!$AU$12:$AU$32,ﾃﾞｰﾀ入力!$AV$12:$AV$32)) -> 4 | AZ7: =IF(AZ3=0,0,LOOKUP(AZ3,ﾃﾞｰﾀ入力!$AU$12:$AU$32,ﾃﾞｰﾀ入力!$AV$12:$AV$32)) -> 4 | BD7: =IF(BD3=0,0,LOOKUP(BD3,ﾃﾞｰﾀ入力!$AU$12:$AU$32,ﾃﾞｰﾀ入力!$AV$12:$AV$32)) -> 4 | BH7: =IF(BH3=0,0,LOOKUP(BH3,ﾃﾞｰﾀ入力!$AU$12:$AU$32,ﾃﾞｰﾀ入力!$AV$12:$AV$32)) -> 3 | BL7: =IF(BL3=0,0,LOOKUP(BL3,ﾃﾞｰﾀ入力!$AU$12:$AU$32,ﾃﾞｰﾀ入力!$AV$12:$AV$32)) -> 2 | BP7: =IF(BP3=0,0,LOOKUP(BP3,ﾃﾞｰﾀ入力!$AU$12:$AU$32,ﾃﾞｰﾀ入力!$AV$12:$AV$32)) -> 2 | BT7: =IF(BT3=0,0,LOOKUP(BT3,ﾃﾞｰﾀ入力!$AU$12:$AU$32,ﾃﾞｰﾀ入力!$AV$12:$AV$32)) -> 2 | BX7: =IF(BX3=0,0,LOOKUP(BX3,ﾃﾞｰﾀ入力!$AU$12:$AU$32,ﾃﾞｰﾀ入力!$AV$12:$AV$32)) -> 2 | CB7: =IF(CB3=0,0,LOOKUP(CB3,ﾃﾞｰﾀ入力!$AU$12:$AU$32,ﾃﾞｰﾀ入力!$AV$12:$AV$32)) -> 0 | CF7: =IF(CF3=0,0,LOOKUP(CF3,ﾃﾞｰﾀ入力!$AU$12:$AU$32,ﾃﾞｰﾀ入力!$AV$12:$AV$32)) -> 0 | CJ7: =IF(CJ3=0,0,LOOKUP(CJ3,ﾃﾞｰﾀ入力!$AU$12:$AU$32,ﾃﾞｰﾀ入力!$AV$12:$AV$32)) -> 0 | CN7: =SUM(P7:CM7) -> 39
I8: 休憩時間 | K8: PLAN | L8: =CHOOSE($CA$1,ﾃﾞｰﾀ入力!W13,ﾃﾞｰﾀ入力!W16,ﾃﾞｰﾀ入力!W19,ﾃﾞｰﾀ入力!W22,ﾃﾞｰﾀ入力!W25,ﾃﾞｰﾀ入力!W28) -> 0 | P8: =CHOOSE($CA$1,ﾃﾞｰﾀ入力!$X13,ﾃﾞｰﾀ入力!$X16,ﾃﾞｰﾀ入力!$X19,ﾃﾞｰﾀ入力!$X22,ﾃﾞｰﾀ入力!$X25,ﾃﾞｰﾀ入力!$X28) -> 0 | T8: =CHOOSE($CA$1,ﾃﾞｰﾀ入力!$Y13,ﾃﾞｰﾀ入力!$Y16,ﾃﾞｰﾀ入力!$Y19,ﾃﾞｰﾀ入力!$Y22,ﾃﾞｰﾀ入力!$Y25,ﾃﾞｰﾀ入力!$Y28) -> 0 | X8: =CHOOSE($CA$1,ﾃﾞｰﾀ入力!$Z13,ﾃﾞｰﾀ入力!$Z16,ﾃﾞｰﾀ入力!$Z19,ﾃﾞｰﾀ入力!$Z22,ﾃﾞｰﾀ入力!$Z25,ﾃﾞｰﾀ入力!$Z28) -> 0 | AB8: =CHOOSE($CA$1,ﾃﾞｰﾀ入力!$AA13,ﾃﾞｰﾀ入力!$AA16,ﾃﾞｰﾀ入力!$AA19,ﾃﾞｰﾀ入力!$AA22,ﾃﾞｰﾀ入力!$AA25,ﾃﾞｰﾀ入力!$AA28) -> 0 | AF8: =CHOOSE($CA$1,ﾃﾞｰﾀ入力!$AB13,ﾃﾞｰﾀ入力!$AB16,ﾃﾞｰﾀ入力!$AB19,ﾃﾞｰﾀ入力!$AB22,ﾃﾞｰﾀ入力!$AB25,ﾃﾞｰﾀ入力!$AB28) -> 0 | AJ8: =CHOOSE($CA$1,ﾃﾞｰﾀ入力!$AC13,ﾃﾞｰﾀ入力!$AC16,ﾃﾞｰﾀ入力!$AC19,ﾃﾞｰﾀ入力!$AC22,ﾃﾞｰﾀ入力!$AC25,ﾃﾞｰﾀ入力!$AC28) -> 0 | AN8: =CHOOSE($CA$1,ﾃﾞｰﾀ入力!$AD13,ﾃﾞｰﾀ入力!$AD16,ﾃﾞｰﾀ入力!$AD19,ﾃﾞｰﾀ入力!$AD22,ﾃﾞｰﾀ入力!$AD25,ﾃﾞｰﾀ入力!$AD28) -> 0 | AR8: =CHOOSE($CA$1,ﾃﾞｰﾀ入力!$AE13,ﾃﾞｰﾀ入力!$AE16,ﾃﾞｰﾀ入力!$AE19,ﾃﾞｰﾀ入力!$AE22,ﾃﾞｰﾀ入力!$AE25,ﾃﾞｰﾀ入力!$AE28) -> 0 | AV8: =CHOOSE($CA$1,ﾃﾞｰﾀ入力!$AF13,ﾃﾞｰﾀ入力!$AF16,ﾃﾞｰﾀ入力!$AF19,ﾃﾞｰﾀ入力!$AF22,ﾃﾞｰﾀ入力!$AF25,ﾃﾞｰﾀ入力!$AF28) -> 0 | AZ8: =CHOOSE($CA$1,ﾃﾞｰﾀ入力!$AG13,ﾃﾞｰﾀ入力!$AG16,ﾃﾞｰﾀ入力!$AG19,ﾃﾞｰﾀ入力!$AG22,ﾃﾞｰﾀ入力!$AG25,ﾃﾞｰﾀ入力!$AG28) -> 0 | BD8: =CHOOSE($CA$1,ﾃﾞｰﾀ入力!$AH13,ﾃﾞｰﾀ入力!$AH16,ﾃﾞｰﾀ入力!$AH19,ﾃﾞｰﾀ入力!$AH22,ﾃﾞｰﾀ入力!$AH25,ﾃﾞｰﾀ入力!$AH28) -> 0 | BH8: =CHOOSE($CA$1,ﾃﾞｰﾀ入力!$AI13,ﾃﾞｰﾀ入力!$AI16,ﾃﾞｰﾀ入力!$AI19,ﾃﾞｰﾀ入力!$AI22,ﾃﾞｰﾀ入力!$AI25,ﾃﾞｰﾀ入力!$AI28) -> 0 | BL8: =CHOOSE($CA$1,ﾃﾞｰﾀ入力!$AJ13,ﾃﾞｰﾀ入力!$AJ16,ﾃﾞｰﾀ入力!$AJ19,ﾃﾞｰﾀ入力!$AJ22,ﾃﾞｰﾀ入力!$AJ25,ﾃﾞｰﾀ入力!$AJ28) -> 0 | BP8: =CHOOSE($CA$1,ﾃﾞｰﾀ入力!$AK13,ﾃﾞｰﾀ入力!$AK16,ﾃﾞｰﾀ入力!$AK19,ﾃﾞｰﾀ入力!$AK22,ﾃﾞｰﾀ入力!$AK25,ﾃﾞｰﾀ入力!$AK28) -> 0 | BT8: =CHOOSE($CA$1,ﾃﾞｰﾀ入力!$AL13,ﾃﾞｰﾀ入力!$AL16,ﾃﾞｰﾀ入力!$AL19,ﾃﾞｰﾀ入力!$AL22,ﾃﾞｰﾀ入力!$AL25,ﾃﾞｰﾀ入力!$AL28) -> 0 | BX8: =CHOOSE($CA$1,ﾃﾞｰﾀ入力!$AM13,ﾃﾞｰﾀ入力!$AM16,ﾃﾞｰﾀ入力!$AM19,ﾃﾞｰﾀ入力!$AM22,ﾃﾞｰﾀ入力!$AM25,ﾃﾞｰﾀ入力!$AM28) -> 0 | CB8: =CHOOSE($CA$1,ﾃﾞｰﾀ入力!$AN13,ﾃﾞｰﾀ入力!$AN16,ﾃﾞｰﾀ入力!$AN19,ﾃﾞｰﾀ入力!$AN22,ﾃﾞｰﾀ入力!$AN25,ﾃﾞｰﾀ入力!$AN28) -> 0 | CF8: =CHOOSE($CA$1,ﾃﾞｰﾀ入力!$AO13,ﾃﾞｰﾀ入力!$AO16,ﾃﾞｰﾀ入力!$AO19,ﾃﾞｰﾀ入力!$AO22,ﾃﾞｰﾀ入力!$AO25,ﾃﾞｰﾀ入力!$AO28) -> 0 | CJ8: =CHOOSE($CA$1,ﾃﾞｰﾀ入力!$AP13,ﾃﾞｰﾀ入力!$AP16,ﾃﾞｰﾀ入力!$AP19,ﾃﾞｰﾀ入力!$AP22,ﾃﾞｰﾀ入力!$AP25,ﾃﾞｰﾀ入力!$AP28) -> 0 | CN8: =SUM(P8:CM8) -> 0
I9: 開閉店業務 | K9: PLAN | L9: =CHOOSE($CA$1,ﾃﾞｰﾀ入力!W14,ﾃﾞｰﾀ入力!W17,ﾃﾞｰﾀ入力!W20,ﾃﾞｰﾀ入力!W23,ﾃﾞｰﾀ入力!W26,ﾃﾞｰﾀ入力!W29) -> 0 | P9: =CHOOSE($CA$1,ﾃﾞｰﾀ入力!$X14,ﾃﾞｰﾀ入力!$X17,ﾃﾞｰﾀ入力!$X20,ﾃﾞｰﾀ入力!$X23,ﾃﾞｰﾀ入力!$X26,ﾃﾞｰﾀ入力!$X29) -> 0 | T9: =CHOOSE($CA$1,ﾃﾞｰﾀ入力!$Y14,ﾃﾞｰﾀ入力!$Y17,ﾃﾞｰﾀ入力!$Y20,ﾃﾞｰﾀ入力!$Y23,ﾃﾞｰﾀ入力!$Y26,ﾃﾞｰﾀ入力!$Y29) -> 0 | X9: =CHOOSE($CA$1,ﾃﾞｰﾀ入力!$Z14,ﾃﾞｰﾀ入力!$Z17,ﾃﾞｰﾀ入力!$Z20,ﾃﾞｰﾀ入力!$Z23,ﾃﾞｰﾀ入力!$Z26,ﾃﾞｰﾀ入力!$Z29) -> 0 | AB9: =CHOOSE($CA$1,ﾃﾞｰﾀ入力!$AA14,ﾃﾞｰﾀ入力!$AA17,ﾃﾞｰﾀ入力!$AA20,ﾃﾞｰﾀ入力!$AA23,ﾃﾞｰﾀ入力!$AA26,ﾃﾞｰﾀ入力!$AA29) -> 0 | AF9: =CHOOSE($CA$1,ﾃﾞｰﾀ入力!$AB14,ﾃﾞｰﾀ入力!$AB17,ﾃﾞｰﾀ入力!$AB20,ﾃﾞｰﾀ入力!$AB23,ﾃﾞｰﾀ入力!$AB26,ﾃﾞｰﾀ入力!$AB29) -> 0 | AJ9: =CHOOSE($CA$1,ﾃﾞｰﾀ入力!$AC14,ﾃﾞｰﾀ入力!$AC17,ﾃﾞｰﾀ入力!$AC20,ﾃﾞｰﾀ入力!$AC23,ﾃﾞｰﾀ入力!$AC26,ﾃﾞｰﾀ入力!$AC29) -> 0 | AN9: =CHOOSE($CA$1,ﾃﾞｰﾀ入力!$AD14,ﾃﾞｰﾀ入力!$AD17,ﾃﾞｰﾀ入力!$AD20,ﾃﾞｰﾀ入力!$AD23,ﾃﾞｰﾀ入力!$AD26,ﾃﾞｰﾀ入力!$AD29) -> 0 | AR9: =CHOOSE($CA$1,ﾃﾞｰﾀ入力!$AE14,ﾃﾞｰﾀ入力!$AE17,ﾃﾞｰﾀ入力!$AE20,ﾃﾞｰﾀ入力!$AE23,ﾃﾞｰﾀ入力!$AE26,ﾃﾞｰﾀ入力!$AE29) -> 0 | AV9: =CHOOSE($CA$1,ﾃﾞｰﾀ入力!$AF14,ﾃﾞｰﾀ入力!$AF17,ﾃﾞｰﾀ入力!$AF20,ﾃﾞｰﾀ入力!$AF23,ﾃﾞｰﾀ入力!$AF26,ﾃﾞｰﾀ入力!$AF29) -> 0 | AZ9: =CHOOSE($CA$1,ﾃﾞｰﾀ入力!$AG14,ﾃﾞｰﾀ入力!$AG17,ﾃﾞｰﾀ入力!$AG20,ﾃﾞｰﾀ入力!$AG23,ﾃﾞｰﾀ入力!$AG26,ﾃﾞｰﾀ入力!$AG29) -> 0 | BD9: =CHOOSE($CA$1,ﾃﾞｰﾀ入力!$AH14,ﾃﾞｰﾀ入力!$AH17,ﾃﾞｰﾀ入力!$AH20,ﾃﾞｰﾀ入力!$AH23,ﾃﾞｰﾀ入力!$AH26,ﾃﾞｰﾀ入力!$AH29) -> 0 | BH9: =CHOOSE($CA$1,ﾃﾞｰﾀ入力!$AI14,ﾃﾞｰﾀ入力!$AI17,ﾃﾞｰﾀ入力!$AI20,ﾃﾞｰﾀ入力!$AI23,ﾃﾞｰﾀ入力!$AI26,ﾃﾞｰﾀ入力!$AI29) -> 0 | BL9: =CHOOSE($CA$1,ﾃﾞｰﾀ入力!$AJ14,ﾃﾞｰﾀ入力!$AJ17,ﾃﾞｰﾀ入力!$AJ20,ﾃﾞｰﾀ入力!$AJ23,ﾃﾞｰﾀ入力!$AJ26,ﾃﾞｰﾀ入力!$AJ29) -> 0 | BP9: =CHOOSE($CA$1,ﾃﾞｰﾀ入力!$AK14,ﾃﾞｰﾀ入力!$AK17,ﾃﾞｰﾀ入力!$AK20,ﾃﾞｰﾀ入力!$AK23,ﾃﾞｰﾀ入力!$AK26,ﾃﾞｰﾀ入力!$AK29) -> 0 | BT9: =CHOOSE($CA$1,ﾃﾞｰﾀ入力!$AL14,ﾃﾞｰﾀ入力!$AL17,ﾃﾞｰﾀ入力!$AL20,ﾃﾞｰﾀ入力!$AL23,ﾃﾞｰﾀ入力!$AL26,ﾃﾞｰﾀ入力!$AL29) -> 0 | BX9: =CHOOSE($CA$1,ﾃﾞｰﾀ入力!$AM14,ﾃﾞｰﾀ入力!$AM17,ﾃﾞｰﾀ入力!$AM20,ﾃﾞｰﾀ入力!$AM23,ﾃﾞｰﾀ入力!$AM26,ﾃﾞｰﾀ入力!$AM29) -> 0 | CB9: =CHOOSE($CA$1,ﾃﾞｰﾀ入力!$AN14,ﾃﾞｰﾀ入力!$AN17,ﾃﾞｰﾀ入力!$AN20,ﾃﾞｰﾀ入力!$AN23,ﾃﾞｰﾀ入力!$AN26,ﾃﾞｰﾀ入力!$AN29) -> 0 | CF9: =CHOOSE($CA$1,ﾃﾞｰﾀ入力!$AO14,ﾃﾞｰﾀ入力!$AO17,ﾃﾞｰﾀ入力!$AO20,ﾃﾞｰﾀ入力!$AO23,ﾃﾞｰﾀ入力!$AO26,ﾃﾞｰﾀ入力!$AO29) -> 0 | CJ9: =CHOOSE($CA$1,ﾃﾞｰﾀ入力!$AP14,ﾃﾞｰﾀ入力!$AP17,ﾃﾞｰﾀ入力!$AP20,ﾃﾞｰﾀ入力!$AP23,ﾃﾞｰﾀ入力!$AP26,ﾃﾞｰﾀ入力!$AP29) -> 0 | CN9: =SUM(P9:CM9) -> 0
I10: 入金・発注・書類 | K10: PLAN | L10: =CHOOSE($CA$1,ﾃﾞｰﾀ入力!W15,ﾃﾞｰﾀ入力!W18,ﾃﾞｰﾀ入力!W21,ﾃﾞｰﾀ入力!W24,ﾃﾞｰﾀ入力!W27,ﾃﾞｰﾀ入力!W30) -> 0 | P10: =CHOOSE($CA$1,ﾃﾞｰﾀ入力!$X15,ﾃﾞｰﾀ入力!$X18,ﾃﾞｰﾀ入力!$X21,ﾃﾞｰﾀ入力!$X24,ﾃﾞｰﾀ入力!$X27,ﾃﾞｰﾀ入力!$X30) -> 0 | T10: =CHOOSE($CA$1,ﾃﾞｰﾀ入力!$Y15,ﾃﾞｰﾀ入力!$Y18,ﾃﾞｰﾀ入力!$Y21,ﾃﾞｰﾀ入力!$Y24,ﾃﾞｰﾀ入力!$Y27,ﾃﾞｰﾀ入力!$Y30) -> 0 | X10: =CHOOSE($CA$1,ﾃﾞｰﾀ入力!$Z15,ﾃﾞｰﾀ入力!$Z18,ﾃﾞｰﾀ入力!$Z21,ﾃﾞｰﾀ入力!$Z24,ﾃﾞｰﾀ入力!$Z27,ﾃﾞｰﾀ入力!$Z30) -> 0 | AB10: =CHOOSE($CA$1,ﾃﾞｰﾀ入力!$AA15,ﾃﾞｰﾀ入力!$AA18,ﾃﾞｰﾀ入力!$AA21,ﾃﾞｰﾀ入力!$AA24,ﾃﾞｰﾀ入力!$AA27,ﾃﾞｰﾀ入力!$AA30) -> 0 | AF10: =CHOOSE($CA$1,ﾃﾞｰﾀ入力!$AB15,ﾃﾞｰﾀ入力!$AB18,ﾃﾞｰﾀ入力!$AB21,ﾃﾞｰﾀ入力!$AB24,ﾃﾞｰﾀ入力!$AB27,ﾃﾞｰﾀ入力!$AB30) -> 0 | AJ10: =CHOOSE($CA$1,ﾃﾞｰﾀ入力!$AC15,ﾃﾞｰﾀ入力!$AC18,ﾃﾞｰﾀ入力!$AC21,ﾃﾞｰﾀ入力!$AC24,ﾃﾞｰﾀ入力!$AC27,ﾃﾞｰﾀ入力!$AC30) -> 0 | AN10: =CHOOSE($CA$1,ﾃﾞｰﾀ入力!$AD15,ﾃﾞｰﾀ入力!$AD18,ﾃﾞｰﾀ入力!$AD21,ﾃﾞｰﾀ入力!$AD24,ﾃﾞｰﾀ入力!$AD27,ﾃﾞｰﾀ入力!$AD30) -> 0 | AR10: =CHOOSE($CA$1,ﾃﾞｰﾀ入力!$AE15,ﾃﾞｰﾀ入力!$AE18,ﾃﾞｰﾀ入力!$AE21,ﾃﾞｰﾀ入力!$AE24,ﾃﾞｰﾀ入力!$AE27,ﾃﾞｰﾀ入力!$AE30) -> 0 | AV10: =CHOOSE($CA$1,ﾃﾞｰﾀ入力!$AF15,ﾃﾞｰﾀ入力!$AF18,ﾃﾞｰﾀ入力!$AF21,ﾃﾞｰﾀ入力!$AF24,ﾃﾞｰﾀ入力!$AF27,ﾃﾞｰﾀ入力!$AF30) -> 0 | AZ10: =CHOOSE($CA$1,ﾃﾞｰﾀ入力!$AG15,ﾃﾞｰﾀ入力!$AG18,ﾃﾞｰﾀ入力!$AG21,ﾃﾞｰﾀ入力!$AG24,ﾃﾞｰﾀ入力!$AG27,ﾃﾞｰﾀ入力!$AG30) -> 0 | BD10: =CHOOSE($CA$1,ﾃﾞｰﾀ入力!$AH15,ﾃﾞｰﾀ入力!$AH18,ﾃﾞｰﾀ入力!$AH21,ﾃﾞｰﾀ入力!$AH24,ﾃﾞｰﾀ入力!$AH27,ﾃﾞｰﾀ入力!$AH30) -> 0 | BH10: =CHOOSE($CA$1,ﾃﾞｰﾀ入力!$AI15,ﾃﾞｰﾀ入力!$AI18,ﾃﾞｰﾀ入力!$AI21,ﾃﾞｰﾀ入力!$AI24,ﾃﾞｰﾀ入力!$AI27,ﾃﾞｰﾀ入力!$AI30) -> 0 | BL10: =CHOOSE($CA$1,ﾃﾞｰﾀ入力!$AJ15,ﾃﾞｰﾀ入力!$AJ18,ﾃﾞｰﾀ入力!$AJ21,ﾃﾞｰﾀ入力!$AJ24,ﾃﾞｰﾀ入力!$AJ27,ﾃﾞｰﾀ入力!$AJ30) -> 0 | BP10: =CHOOSE($CA$1,ﾃﾞｰﾀ入力!$AK15,ﾃﾞｰﾀ入力!$AK18,ﾃﾞｰﾀ入力!$AK21,ﾃﾞｰﾀ入力!$AK24,ﾃﾞｰﾀ入力!$AK27,ﾃﾞｰﾀ入力!$AK30) -> 0 | BT10: =CHOOSE($CA$1,ﾃﾞｰﾀ入力!$AL15,ﾃﾞｰﾀ入力!$AL18,ﾃﾞｰﾀ入力!$AL21,ﾃﾞｰﾀ入力!$AL24,ﾃﾞｰﾀ入力!$AL27,ﾃﾞｰﾀ入力!$AL30) -> 0 | BX10: =CHOOSE($CA$1,ﾃﾞｰﾀ入力!$AM15,ﾃﾞｰﾀ入力!$AM18,ﾃﾞｰﾀ入力!$AM21,ﾃﾞｰﾀ入力!$AM24,ﾃﾞｰﾀ入力!$AM27,ﾃﾞｰﾀ入力!$AM30) -> 0 | CB10: =CHOOSE($CA$1,ﾃﾞｰﾀ入力!$AN15,ﾃﾞｰﾀ入力!$AN18,ﾃﾞｰﾀ入力!$AN21,ﾃﾞｰﾀ入力!$AN24,ﾃﾞｰﾀ入力!$AN27,ﾃﾞｰﾀ入力!$AN30) -> 0 | CF10: =CHOOSE($CA$1,ﾃﾞｰﾀ入力!$AO15,ﾃﾞｰﾀ入力!$AO18,ﾃﾞｰﾀ入力!$AO21,ﾃﾞｰﾀ入力!$AO24,ﾃﾞｰﾀ入力!$AO27,ﾃﾞｰﾀ入力!$AO30) -> 0 | CJ10: =CHOOSE($CA$1,ﾃﾞｰﾀ入力!$AP15,ﾃﾞｰﾀ入力!$AP18,ﾃﾞｰﾀ入力!$AP21,ﾃﾞｰﾀ入力!$AP24,ﾃﾞｰﾀ入力!$AP27,ﾃﾞｰﾀ入力!$AP30) -> 0 | CN10: =SUM(P10:CM10) -> 0
I11: 合計時間 | K11: PLAN | L11: =SUM(L7:O10) -> 0 | P11: =SUM(P7:S10) -> 0 | T11: =SUM(T7:W10) -> 0 | X11: =SUM(X7:AA10) -> 2 | AB11: =SUM(AB7:AE10) -> 2 | AF11: =SUM(AF7:AI10) -> 2 | AJ11: =SUM(AJ7:AM10) -> 2 | AN11: =SUM(AN7:AQ10) -> 4 | AR11: =SUM(AR7:AU10) -> 4 | AV11: =SUM(AV7:AY10) -> 4 | AZ11: =SUM(AZ7:BC10) -> 4 | BD11: =SUM(BD7:BG10) -> 4 | BH11: =SUM(BH7:BK10) -> 3 | BL11: =SUM(BL7:BO10) -> 2 | BP11: =SUM(BP7:BS10) -> 2 | BT11: =SUM(BT7:BW10) -> 2 | BX11: =SUM(BX7:CA10) -> 2 | CB11: =SUM(CB7:CE10) -> 0 | CF11: =SUM(CF7:CI10) -> 0 | CJ11: =SUM(CJ7:CM10) -> 0 | CN11: =SUM(P11:CM11) -> 39
